<?xml version="1.0" ?>
<!-- =================================================================================== -->
<!-- |    This document was autogenerated by xacro from centauro.urdf.xacro            | -->
<!-- |    EDITING THIS FILE BY HAND IS NOT RECOMMENDED                                 | -->
<!-- =================================================================================== -->
<robot name="centauro" xmlns:xacro="http://www.ros.org/wiki/xacro">
  <!-- /constants -->
  <!-- Here all arguments from launch file are evaluated to the final xacro poropeties.
     Also all the parameter dependencies are resolved-->
  <material name="grey">
    <color rgba="0.5 0.5 0.5 1"/>
  </material>
  <material name="dark_grey">
    <color rgba="0.3 0.3 0.3 1"/>
  </material>
  <material name="blue">
    <color rgba="0.0 0.2 0.3 1"/>
  </material>
  <material name="red">
    <color rgba="0.5 0.1 0.2 1"/>
  </material>
  <material name="black">
    <color rgba="0.0 0.0 0.0 1"/>
  </material>
  <!-- Here all arguments from launch file are evaluated to the final xacro poropeties.
     Also all the parameter dependencies are resolved-->
  <!-- load proper collision model -->
  <!-- load proper collision model -->
  <!-- load proper collision model -->
  <!-- load proper collision model -->
  <!-- Here all arguments from launch file are evaluated to the final xacro poropeties.
     Also all the parameter dependencies are resolved-->
  <!-- load proper collision model -->
  <!-- load proper collision model -->
  <!-- load proper collision model -->
  <!-- load proper collision model -->
  <!-- /macro legs -->
  <!--xacro:if value="${arms}">
  <xacro:include filename="$(find centauro)/centauro_urdf/urdf/centauro_arm.urdf.xacro"/>
</xacro:if-->
  <!-- /other files -->
  <!-- reference -->
  <!-- <link name="base_link"/>

<joint name="base_joint" type="fixed">
   <origin xyz="0 0 0"/>
   <parent link="base_link"/>
   <child link="world"/>
</joint>
-->
  <link name="pelvis">
    <inertial>
      <origin xyz="0.0013890071 -0.0015989148 0.063101012"/>
      <mass value="16.097574"/>
      <inertia ixx="0.23912627" ixy="-0.0050541269" ixz="-0.019746055" iyy="0.71430078" iyz="0.0002131204" izz="0.81870448"/>
    </inertial>
    <visual>
      <origin rpy="0.0 0.0 0.0" xyz="0.0 0 0.0"/>
      <geometry>
        <mesh filename="package://centauro/centauro_urdf/meshes/simplified/pelvis.stl" scale="0.001 0.001 0.001"/>
      </geometry>
    </visual>
    <collision>
      <origin rpy="0.0 0.0 0.0" xyz="0.0 0 0.0"/>
      <geometry>
        <mesh filename="package://centauro/centauro_urdf/meshes/convex_hull/pelvis.stl" scale="0.001 0.001 0.001"/>
      </geometry>
    </collision>
  </link>
  <link name="imu_link">
    <inertial>
      <mass value="0.0"/>
      <inertia ixx="0.0" ixy="0.0" ixz="0.0" iyy="0.0" iyz="0.0" izz="0.0"/>
    </inertial>
  </link>
  <joint name="imu_joint" type="fixed">
    <parent link="pelvis"/>
    <origin rpy="0.0 0.0 0.0" xyz="0.248316 0.0 0.015"/>
    <child link="imu_link"/>
  </joint>
  <!-- torso links -->
  <link name="torso_2">
    <inertial>
      <origin xyz="-0.019497794 0.0045317835 0.13768283"/>
      <mass value="11.492689"/>
      <inertia ixx="0.063643392" ixy="8.939e-05" ixz="-0.00086873" iyy="0.02680235" iyz="-4.657e-05" izz="0.04743015"/>
    </inertial>
    <visual>
      <origin rpy="0.0 0.0 0.0" xyz="0.0 0 0.0"/>
      <geometry>
        <mesh filename="package://centauro/centauro_urdf/meshes/simplified/link1.stl" scale="0.001 0.001 0.001"/>
      </geometry>
    </visual>
    <collision>
      <origin rpy="0.0 0.0 0.0" xyz="0.0 0 0.0"/>
      <geometry>
        <mesh filename="package://centauro/centauro_urdf/meshes/convex_hull/link1.stl" scale="0.001 0.001 0.001"/>
      </geometry>
    </collision>
  </link>
  <!-- /torso links -->
  <!-- torso joints -->
  <joint name="torso_yaw" type="revolute">
    <parent link="pelvis"/>
    <origin xyz="0.2 0.0 0.256"/>
    <child link="torso_2"/>
    <axis xyz="0 0 1"/>
    <limit effort="147" lower="-2.618" upper="2.618" velocity="5.7"/>
    <!-- TODO -->
  </joint>
  <!-- /torso joints -->
  <transmission name="t_torso_yaw">
    <type> transmission_interface/SimpleTransmission</type>
    <joint name="torso_yaw">
      <hardwareInterface>hardware_interface/EffortJointInterface</hardwareInterface>
    </joint>
    <actuator name="motor_torso_yaw">
      <hardwareInterface>hardware_interface/EffortJointInterface</hardwareInterface>
      <machanicalReduction>1</machanicalReduction>
    </actuator>
    <robotNamespace>/centauro</robotNamespace>
  </transmission>
  <!-- /torso actuators -->
  <!--<xacro:include filename="$(find centauro)/centauro_urdf/urdf/sensors/kinect2.urdf.xacro"/> -->
 
  <!-- head links -->
  <link name="neck_1">
    <inertial>
      <origin xyz="0.040479674 0.021377573 -0.014595112"/>
      <mass value="0.33878686"/>
      <inertia ixx="0.0003718568" ixy="-9.42983e-05" ixz="-2.80644e-05" iyy="0.0001886879" iyz="-1.54534e-05" izz="0.0005023443"/>
    </inertial>
    <visual>
      <origin rpy="0.0 0.0 0.0" xyz="0.0 0 0.0"/>
      <geometry>
        <mesh filename="package://centauro/centauro_urdf/meshes/neck_yaw.stl" scale="0.001 0.001 0.001"/>
      </geometry>
    </visual>
    <collision>
      <origin rpy="0.0 0.0 0.0" xyz="0.0 0 0.0"/>
      <geometry>
        <mesh filename="package://centauro/centauro_urdf/meshes/convex_hull/neck_yaw.stl" scale="0.001 0.001 0.001"/>
      </geometry>
    </collision>
  </link>
  <link name="neck_2">
    <inertial>
      <origin xyz="0.048466918 -0.059852318 -0.0085314894"/>
      <mass value="0.78526942"/>
      <inertia ixx="0.0004682345" ixy="-1.05438e-05" ixz="7.24398e-05" iyy="0.0002635246" iyz="1.6904e-06" izz="0.0003763351"/>
    </inertial>
    <visual>
      <origin rpy="0.0 0.0 0.0" xyz="0.0 0 0.0"/>
      <geometry>
        <mesh filename="package://centauro/centauro_urdf/meshes/neck_pitch.stl" scale="0.001 0.001 0.001"/>
      </geometry>
    </visual>
    <collision>
      <origin rpy="0.0 0.0 0.0" xyz="0.0 0 0.0"/>
      <geometry>
        <mesh filename="package://centauro/centauro_urdf/meshes/convex_hull/neck_pitch.stl" scale="0.001 0.001 0.001"/>
      </geometry>
    </collision>
  </link>
  <link name="neck_3">
    <inertial>
      <origin xyz="0.048466918 -0.059852318 -0.0085314894"/>
      <mass value="0.78526942"/>
      <inertia ixx="0.0004682345" ixy="-1.05438e-05" ixz="7.24398e-05" iyy="0.0002635246" iyz="1.6904e-06" izz="0.0003763351"/>
    </inertial>
    <visual>
      <origin rpy="0.0 0.0 0.0" xyz="0.0 0 0.0"/>
      <geometry>
        <mesh filename="package://centauro/centauro_urdf/meshes/simplified/mesh_lidar.stl" scale="0.001 0.001 0.001"/>
      </geometry>
    </visual>
    <collision>
      <origin rpy="0.0 0.0 0.0" xyz="0.0 0 0.0"/>
      <geometry>
        <mesh filename="package://centauro/centauro_urdf/meshes/convex_hull/velodyne.stl" scale="0.001 0.001 0.001"/>
      </geometry>
    </collision>
  </link>
  <!-- /head links -->
  <!-- sensors links -->
  <link name="camera_central">
    <inertial>
      <origin xyz="0.0 0.0 0.0"/>
      <mass value="0.1"/>
      <inertia ixx="1e-06" ixy="0.0" ixz="0.0" iyy="1e-06" iyz="0.0" izz="1e-06"/>
    </inertial>
  </link>
  <link name="camera_left">
    <inertial>
      <origin xyz="0.0 0.0 0.0"/>
      <mass value="0.1"/>
      <inertia ixx="1e-06" ixy="0.0" ixz="0.0" iyy="1e-06" iyz="0.0" izz="1e-06"/>
    </inertial>
  </link>
  <link name="camera_right">
    <inertial>
      <origin xyz="0.0 0.0 0.0"/>
      <mass value="0.1"/>
      <inertia ixx="1e-06" ixy="0.0" ixz="0.0" iyy="1e-06" iyz="0.0" izz="1e-06"/>
    </inertial>
  </link>
  <link name="kinect">
    <inertial>
      <origin xyz="0.0 0.0 0.0"/>
      <mass value="0.1"/>
      <inertia ixx="1e-06" ixy="0.0" ixz="0.0" iyy="1e-06" iyz="0.0" izz="1e-06"/>
    </inertial>
  </link>
  <link name="velodyne_mount">
    <inertial>
      <origin xyz="0.0 0.0 0.0"/>
      <mass value="0.1"/>
      <inertia ixx="1e-06" ixy="0.0" ixz="0.0" iyy="1e-06" iyz="0.0" izz="1e-06"/>
    </inertial>
  </link>
  <!-- /sensors links -->
  <!-- head joints -->
  <joint name="neck_yaw" type="revolute">
    <parent link="torso_2"/>
    <origin xyz="0.0 0.0 0.2795"/>
    <child link="neck_1"/>
    <axis xyz="0 0 1"/>
    <limit effort="35" lower="-0.78539816" upper="0.78539816" velocity="5.7"/>
    <!-- TODO -->
    <dynamics friction="10.0"/>
  </joint>
  <joint name="neck_pitch" type="revolute">
    <parent link="neck_1"/>
    <origin xyz="0.054 0.0596 -0.0124975"/>
    <child link="neck_2"/>
    <axis xyz="0 1 0"/>
    <limit effort="35" lower="-0.34906585" upper="0.78539816" velocity="5.7"/>
    <!-- TODO -->
    <dynamics friction="10.0"/>
  </joint>
  <joint name="neck_velodyne" type="continuous">
    <parent link="torso_2"/>
    <origin xyz="0.055 0.0 0.473262"/>
    <child link="neck_3"/>
    <axis xyz="0 0 1"/>
    <limit effort="35" velocity="5.7"/>
    <!-- TODO -->
    <dynamics damping="0.2" friction="10.0"/>
  </joint>
  <!-- sensors transformations  -->
  <joint name="j_camera_central" type="fixed">
    <parent link="torso_2"/>
    <origin rpy="0.0 0.349065586018 0.0" xyz="0.0559593 5e-12 0.390626"/>
    <child link="camera_central"/>
  </joint>
  <joint name="j_camera_left" type="fixed">
    <parent link="torso_2"/>
    <origin rpy="0.0 0.349065586018 1.2217302006" xyz="0.0191392 0.0525845 0.390626"/>
    <child link="camera_left"/>
  </joint>
  <joint name="j_camera_right" type="fixed">
    <parent link="torso_2"/>
    <origin rpy="0.0 0.349065586018 -1.2217302006" xyz="0.0191392 -0.0525845 0.390626"/>
    <child link="camera_right"/>
  </joint>
  <joint name="j_kinect" type="fixed">
    <parent link="neck_2"/>
    <origin rpy="0.0 0.0 0.0" xyz="0.03 -0.0596 0.045855"/>
    <child link="kinect"/>
  </joint>
  <link name="kinect2_rgb_frame"/>
  <joint name="j_kinect2_rgb_frame" type="fixed">
    <parent link="kinect"/>
    <child link="kinect2_rgb_frame"/>
    <origin xyz="0.050 -0.110 -0.035"/>
  </joint>
  <link name="kinect2_rgb_optical_frame"/>
  <joint name="j_kinect_optical_frame" type="fixed">
    <parent link="kinect2_rgb_frame"/>
    <child link="kinect2_rgb_optical_frame"/>
    <origin rpy=" -1.5707963268 0 -1.5707963268"/>
  </joint>
  <joint name="j_velodyne" type="fixed">
    <parent link="neck_3"/>
    <origin rpy="0.0 0.0 -3.14159265359" xyz="-0.138 0.0 -0.033" />
    <child link="velodyne_mount"/>
  </joint>
  <!-- Kinect simulation -->
  <!-- /sensors transformations -->
  <link name="velodyne_calib"/>
  <joint name="velodyne_calib" type="fixed">
    <parent link="neck_3"/>
    <origin rpy="0 1.57 -1.57" xyz="-0.175768 0 -0.034219"/>
    <child link="velodyne_calib"/>
  </joint>


  <!-- /torso -->
  <!-- arms -->
  <!--
<xacro:if value="${left_arm == 'true'}">
   <xacro:centauro_arm arm_num="1"  rot="1"  parent="torso_2" end_effector="${left_end_effector}" mount="${left_arm_mount}">
      <origin xyz="${Shoulder_1_Ox} ${Shoulder_1_Oy} ${Shoulder_1_Oz}" rpy="${Shoulder_1_roll} ${Shoulder_1_pitch} ${Shoulder_1_yaw}"/>
   </xacro:centauro_arm>
</xacro:if>
<xacro:if value="${right_arm == 'true'}">
   <xacro:centauro_arm arm_num="2" rot="-1"  parent="torso_2" end_effector="${right_end_effector}" mount="${right_arm_mount}">
      <origin xyz="${Shoulder_1_Ox} ${-Shoulder_1_Oy} ${Shoulder_1_Oz}" rpy="${Shoulder_1_roll} ${Shoulder_1_pitch} ${-Shoulder_1_yaw}" />
   </xacro:centauro_arm>
</xacro:if>
-->
  <!-- RIGHT ARM -->
  <link name="RShp">
    <inertial>
      <origin rpy="0 0 0" xyz="-0.0074457212 -0.03410796 0.00010978102"/>
      <mass value="1.9628675"/>
      <inertia ixx="0.0053547717" ixy="-0.00036428926" ixz="1.5089568e-05" iyy="0.0033923328" iyz="-5.5692312e-05" izz="0.0068921413"/>
    </inertial>
    <visual>
      <origin rpy="0 0 0" xyz="0 0 0"/>
      <geometry name="RShp_visual">
        <mesh filename="package://cogimon_urdf/meshes/ShoulderPitch.STL" scale="0.001 0.001 0.001"/>
      </geometry>
      <material name="green"/>
    </visual>
    <collision>
      <origin rpy="0 0 0" xyz="0 0 0"/>
      <geometry name="RShp_collision">
        <mesh filename="package://cogimon_urdf/meshes/simple/ShoulderPitch.STL" scale="0.001 0.001 0.001"/>
      </geometry>
    </collision>
  </link>
  <link name="RShr">
    <inertial>
      <origin rpy="0 0 0" xyz="0.058142302 -5.7450803e-05 -0.077477683"/>
      <mass value="1.8595811"/>
      <inertia ixx="0.013776643" ixy="-3.7788675e-05" ixz="0.0037690171" iyy="0.015677464" iyz="9.4893549e-06" izz="0.0046317657"/>
    </inertial>
    <visual>
      <origin rpy="0 0 0" xyz="0 0 0"/>
      <geometry name="RShr_visual">
        <mesh filename="package://cogimon_urdf/meshes/ShoulderRoll.STL" scale="0.001 0.001 0.001"/>
      </geometry>
      <material name="dark_grey"/>
    </visual>
    <collision>
      <origin rpy="0 0 0" xyz="0 0 0"/>
      <geometry name="RShr_collision">
        <mesh filename="package://cogimon_urdf/meshes/simple/ShoulderRoll.STL" scale="0.001 0.001 0.001"/>
      </geometry>
    </collision>
  </link>
  <link name="RShy">
    <inertial>
      <origin rpy="0 0 0" xyz="0.014625194 -0.0008172672 -0.028333545"/>
      <mass value="1.6678109"/>
      <inertia ixx="0.0064480435" ixy="0.00015639093" ixz="0.0012205359" iyy="0.0073372077" iyz="-8.9941532e-05" izz="0.0036738448"/>
    </inertial>
    <visual>
      <origin rpy="0 0 0" xyz="0 0 0"/>
      <geometry name="RShy_visual">
        <mesh filename="package://cogimon_urdf/meshes/ShoulderYaw.STL" scale="0.001 0.001 0.001"/>
      </geometry>
      <material name="green"/>
    </visual>
    <collision>
      <origin rpy="0 0 0" xyz="0 0 0"/>
      <geometry name="RShy_collision">
        <mesh filename="package://cogimon_urdf/meshes/simple/ShoulderYaw.STL" scale="0.001 0.001 0.001"/>
      </geometry>
    </collision>
  </link>
  <link name="RElb">
    <inertial>
      <origin rpy="0 0 0" xyz="-0.0076833067 0.040302205 -0.043492779"/>
      <mass value="1.3157289"/>
      <inertia ixx="0.004330394" ixy="0.00011737391" ixz="-0.00041923199" iyy="0.0038539919" iyz="0.00079573038" izz="0.0017594689"/>
    </inertial>
    <visual>
      <origin rpy="0 0 0" xyz="0 0 0"/>
      <geometry name="RElb_visual">
        <mesh filename="package://cogimon_urdf/meshes/Elbow.STL" scale="0.001 0.001 0.001"/>
      </geometry>
      <material name="dark_grey"/>
    </visual>
    <collision>
      <origin rpy="0 0 0" xyz="0 0 0"/>
      <geometry name="RElb_collision">
        <mesh filename="package://cogimon_urdf/meshes/simple/Elbow.STL" scale="0.001 0.001 0.001"/>
      </geometry>
    </collision>
  </link>
  <link name="RForearm">
    <inertial>
      <origin rpy="0 0 0" xyz="-0.00011079615 -0.011590836 -0.07816026"/>
      <mass value="1.4908547"/>
      <inertia ixx="0.0085692128" ixy="-1.7856252e-05" ixz="1.9379365e-05" iyy="0.0077454159" iyz="0.00032860094" izz="0.0027441921"/>
    </inertial>
    <visual>
      <origin rpy="0 0 0" xyz="0 0 0"/>
      <geometry name="RForearm_visual">
        <mesh filename="package://cogimon_urdf/meshes/Forearm.STL" scale="0.001 0.001 0.001"/>
      </geometry>
      <material name="green"/>
    </visual>
    <collision>
      <origin rpy="0 0 0" xyz="0 0 0"/>
      <geometry name="RForearm_collision">
        <mesh filename="package://cogimon_urdf/meshes/simple/Forearm.STL" scale="0.001 0.001 0.001"/>
      </geometry>
    </collision>
  </link>
  <link name="RWrMot2">
    <inertial>
      <origin rpy="0 0 0" xyz="-4.6502396e-06 0.038014094 -0.069926878"/>
      <mass value="1.1263612"/>
      <inertia ixx="0.0051871784" ixy="-2.724437e-05" ixz="2.2833496e-06" iyy="0.0048037789" iyz="0.00072165653" izz="0.0012771388"/>
    </inertial>
    <visual>
      <origin rpy="0 0 0" xyz="0 0 0"/>
      <geometry name="RWrMot2_visual">
        <mesh filename="package://cogimon_urdf/meshes/ForearmPitch.STL" scale="0.001 0.001 0.001"/>
      </geometry>
      <material name="dark_grey"/>
    </visual>
    <collision>
      <origin rpy="0 0 0" xyz="0 0 0"/>
      <geometry name="RWrMot2_collision">
        <mesh filename="package://cogimon_urdf/meshes/simple/ForearmPitch.STL" scale="0.001 0.001 0.001"/>
      </geometry>
    </collision>
  </link>
  <link name="RWrMot3">
    <inertial>
      <origin rpy="0 0 0" xyz="0 0 0.03127057"/>
      <mass value="2.7966428e-01"/>
      <inertia ixx="0.00014415192" ixy="9.8651826e-08" ixz="0" iyy="0.0001441701" iyz="0" izz="6.0500616e-05"/>
    </inertial>
    <visual>
      <origin rpy="0 0 0" xyz="0 0 0"/>
      <geometry name="RWrMot3_visual">
        <mesh filename="package://cogimon_urdf/meshes/ForearmYaw.STL" scale="0.001 0.001 0.001"/>
      </geometry>
      <material name="green"/>
    </visual>
    <collision>
      <origin rpy="0 0 0" xyz="0 0 0"/>
      <geometry name="RWrMot3_collision">
        <mesh filename="package://cogimon_urdf/meshes/simple/ForearmYaw.STL" scale="0.001 0.001 0.001"/>
      </geometry>
    </collision>
  </link>
  <link name="r_wrist">
    <inertial>
      <origin rpy="0 0 0" xyz="8.2161929e-05 -0.0026334189 -0.016465877"/>
      <mass value="3.7827821e-01"/>
      <inertia ixx="0.00023321716" ixy="-2.3681435e-06" ixz="-1.8039102e-06" iyy="0.00020626291" iyz="-3.158829e-05" izz="0.00027399881"/>
    </inertial>
    <visual>
      <origin rpy="3.14159265359 0 0" xyz="0 0 0"/>
      <geometry name="RShp_visual">
        <mesh filename="package://cogimon_urdf/meshes/Wrist.STL" scale="0.001 0.001 0.001"/>
      </geometry>
      <material name="dark_grey"/>
    </visual>
    <collision>
      <origin rpy="3.14159265359 0 0" xyz="0 0 0"/>
      <geometry name="RShp_collision">
        <mesh filename="package://cogimon_urdf/meshes/simple/Wrist.STL" scale="0.001 0.001 0.001"/>
      </geometry>
    </collision>
  </link>
  <joint name="j_arm2_1" type="revolute">
    <parent link="DWYTorso"/>
    <child link="RShp"/>
    <origin rpy="-0.174533 0 0.5235988" xyz="0.0457475 -0.169137 0.155126"/>
    <axis xyz="0 1 0"/>
    <limit effort="140" lower="-3.359" upper="1.606" velocity="6.283"/>
    <dynamics damping="3.0" friction="0"/>
  </joint>
  <joint name="j_arm2_2" type="revolute">
    <parent link="RShp"/>
    <child link="RShr"/>
    <origin rpy="0.1745327 0 0" xyz="-0.09015 -0.062 0"/>
    <axis xyz="1 0 0"/>
    <limit effort="140" lower="-3.43" upper="0.0" velocity="6.283"/>
    <dynamics damping="3.0" friction="0"/>
  </joint>
  <joint name="j_arm2_3" type="revolute">
    <parent link="RShr"/>
    <child link="RShy"/>
    <origin rpy="0 0 0" xyz="0.09015 0 -0.21815"/>
    <axis xyz="0 0 1"/>
    <limit effort="120" lower="-2.55" upper="2.55" velocity="6.283"/>
    <dynamics damping="3.0" friction="0"/>
  </joint>
  <joint name="j_arm2_4" type="revolute">
    <parent link="RShy"/>
    <child link="RElb"/>
    <origin rpy="0 0 0" xyz="0.045 -0.05515 -0.074"/>
    <axis xyz="0 1 0"/>
    <limit effort="120" lower="-2.488" upper="0.292" velocity="6.283"/>
    <dynamics damping="3.0" friction="0"/>
  </joint>
  <joint name="j_arm2_5" type="revolute">
    <parent link="RElb"/>
    <child link="RForearm"/>
    <origin rpy="0 0 0" xyz="-0.015 0.05515 -0.095"/>
    <axis xyz="0 0 1"/>
    <limit effort="35" lower="-2.55" upper="2.55" velocity="6.283"/>
    <dynamics damping="0.03" friction="0"/>
  </joint>
  <joint name="j_arm2_6" type="revolute">
    <parent link="RForearm"/>
    <child link="RWrMot2"/>
    <origin rpy="0 0 0" xyz="0 -0.049 -0.156"/>
    <axis xyz="0 1 0"/>
    <limit effort="35" lower="-1.542" upper="1.508" velocity="6.283"/>
    <dynamics damping="0.03" friction="0"/>
  </joint>
  <joint name="j_arm2_7" type="revolute">
    <parent link="RWrMot2"/>
    <child link="RWrMot3"/>
    <origin rpy="0 0 0" xyz="0 0.049 -0.174"/>
    <axis xyz="0 0 1"/>
    <limit effort="20" lower="-2.55" upper="2.55" velocity="6.283"/>
    <dynamics damping="0.03" friction="0"/>
  </joint>
  <joint name="r_wrist_joint" type="fixed">
    <parent link="RWrMot3"/>
    <child link="r_wrist"/>
    <origin rpy="0 0 0" xyz="0 0 0"/>
  </joint>
  <!-- LEFT ARM -->
  <link name="LShp">
    <inertial>
      <origin rpy="0 0 0" xyz="-0.0074457212 0.03410796 0.00010978102"/>
      <mass value="1.9628675"/>
      <inertia ixx="0.0053547717" ixy="0.00036428926" ixz="1.5089568e-05" iyy="0.0033923328" iyz="5.5692312e-05" izz="0.0068921413"/>
    </inertial>
    <visual>
      <origin rpy="0 0 0" xyz="0 0 0"/>
      <geometry name="LShp_visual">
        <mesh filename="package://cogimon_urdf/meshes/ShoulderPitch.STL" scale="0.001 -0.001 0.001"/>
      </geometry>
      <material name="green"/>
    </visual>
    <collision>
      <origin rpy="0 0 0" xyz="0 0 0"/>
      <geometry name="LShp_collision">
        <mesh filename="package://cogimon_urdf/meshes/simple/ShoulderPitch.STL" scale="0.001 -0.001 0.001"/>
      </geometry>
    </collision>
  </link>
  <link name="LShr">
    <inertial>
      <origin rpy="0 0 0" xyz="0.058142302 5.7450803e-05 -0.077477683"/>
      <mass value="1.8595811"/>
      <inertia ixx="0.013776643" ixy="3.7788675e-05" ixz="0.0037690171" iyy="0.015677464" iyz="-9.4893549e-06" izz="0.0046317657"/>
    </inertial>
    <visual>
      <origin rpy="0 0 0" xyz="0 0 0"/>
      <geometry name="LShr_visual">
        <mesh filename="package://cogimon_urdf/meshes/ShoulderRoll.STL" scale="0.001 -0.001 0.001"/>
      </geometry>
      <material name="dark_grey"/>
    </visual>
    <collision>
      <origin rpy="0 0 0" xyz="0 0 0"/>
      <geometry name="LShr_collision">
        <mesh filename="package://cogimon_urdf/meshes/simple/ShoulderRoll.STL" scale="0.001 -0.001 0.001"/>
      </geometry>
    </collision>
  </link>
  <link name="LShy">
    <inertial>
      <origin rpy="0 0 0" xyz="0.014625194 0.0008172672 -0.028333545"/>
      <mass value="1.6678109"/>
      <inertia ixx="0.0064480435" ixy="-0.00015639093" ixz="0.0012205359" iyy="0.0073372077" iyz="8.9941532e-05" izz="0.0036738448"/>
    </inertial>
    <visual>
      <origin rpy="0 0 0" xyz="0 0 0"/>
      <geometry name="LShy_visual">
        <mesh filename="package://cogimon_urdf/meshes/ShoulderYaw.STL" scale="0.001 -0.001 0.001"/>
      </geometry>
      <material name="green"/>
    </visual>
    <collision>
      <origin rpy="0 0 0" xyz="0 0 0"/>
      <geometry name="LShy_collision">
        <mesh filename="package://cogimon_urdf/meshes/simple/ShoulderYaw.STL" scale="0.001 -0.001 0.001"/>
      </geometry>
    </collision>
  </link>
  <link name="LElb">
    <inertial>
      <origin rpy="0 0 0" xyz="-0.0076833067 -0.040302205 -0.043492779"/>
      <mass value="1.3157289"/>
      <inertia ixx="0.004330394" ixy="-0.00011737391" ixz="-0.00041923199" iyy="0.0038539919" iyz="-0.00079573038" izz="0.0017594689"/>
    </inertial>
    <visual>
      <origin rpy="0 0 0" xyz="0 0 0"/>
      <geometry name="LElb_visual">
        <mesh filename="package://cogimon_urdf/meshes/Elbow.STL" scale="0.001 -0.001 0.001"/>
      </geometry>
      <material name="dark_grey"/>
    </visual>
    <collision>
      <origin rpy="0 0 0" xyz="0 0 0"/>
      <geometry name="LElb_collision">
        <mesh filename="package://cogimon_urdf/meshes/simple/Elbow.STL" scale="0.001 -0.001 0.001"/>
      </geometry>
    </collision>
  </link>
  <link name="LForearm">
    <inertial>
      <origin rpy="0 0 0" xyz="-0.00011079615 0.011590836 -0.07816026"/>
      <mass value="1.4908547"/>
      <inertia ixx="0.0085692128" ixy="1.7856252e-05" ixz="1.9379365e-05" iyy="0.0077454159" iyz="-0.00032860094" izz="0.0027441921"/>
    </inertial>
    <visual>
      <origin rpy="0 0 0" xyz="0 0 0"/>
      <geometry name="LForearm_visual">
        <mesh filename="package://cogimon_urdf/meshes/Forearm.STL" scale="0.001 -0.001 0.001"/>
      </geometry>
      <material name="green"/>
    </visual>
    <collision>
      <origin rpy="0 0 0" xyz="0 0 0"/>
      <geometry name="LForearm_collision">
        <mesh filename="package://cogimon_urdf/meshes/simple/Forearm.STL" scale="0.001 -0.001 0.001"/>
      </geometry>
    </collision>
  </link>
  <link name="LWrMot2">
    <inertial>
      <origin rpy="0 0 0" xyz="-4.6502396e-06 -0.038014094 -0.069926878"/>
      <mass value="1.1263612"/>
      <inertia ixx="0.0051871784" ixy="2.724437e-05" ixz="2.2833496e-06" iyy="0.0048037789" iyz="-0.00072165653" izz="0.0012771388"/>
    </inertial>
    <visual>
      <origin rpy="0 0 0" xyz="0 0 0"/>
      <geometry name="LWrMot2_visual">
        <mesh filename="package://cogimon_urdf/meshes/ForearmPitch.STL" scale="0.001 -0.001 0.001"/>
      </geometry>
      <material name="dark_grey"/>
    </visual>
    <collision>
      <origin rpy="0 0 0" xyz="0 0 0"/>
      <geometry name="LWrMot2_collision">
        <mesh filename="package://cogimon_urdf/meshes/simple/ForearmPitch.STL" scale="0.001 -0.001 0.001"/>
      </geometry>
    </collision>
  </link>
  <link name="LWrMot3">
    <inertial>
      <origin rpy="0 0 0" xyz="0 0 0.03127057"/>
      <mass value="2.7966428e-01"/>
      <inertia ixx="0.00014415192" ixy="9.8651826e-08" ixz="0" iyy="0.0001441701" iyz="0" izz="6.0500616e-05"/>
    </inertial>
    <visual>
      <origin rpy="0 0 0" xyz="0 0 0"/>
      <geometry name="LWrMot3_visual">
        <mesh filename="package://cogimon_urdf/meshes/ForearmYaw.STL" scale="0.001 -0.001 0.001"/>
      </geometry>
      <material name="green"/>
    </visual>
    <collision>
      <origin rpy="0 0 0" xyz="0 0 0"/>
      <geometry name="LWrMot3_collision">
        <mesh filename="package://cogimon_urdf/meshes/simple/ForearmYaw.STL" scale="0.001 -0.001 0.001"/>
      </geometry>
    </collision>
  </link>
  <link name="l_wrist">
    <inertial>
      <origin rpy="0 0 0" xyz="8.2161929e-05 0.0026334189 -0.016465877"/>
      <mass value="3.7827821e-01"/>
      <inertia ixx="0.00023321716" ixy="2.3681435e-06" ixz="-1.8039102e-06" iyy="0.00020626291" iyz="3.158829e-05" izz="0.00027399881"/>
    </inertial>
    <visual>
      <origin rpy="3.14159265359 0 0" xyz="0 0 0"/>
      <geometry name="LShp_visual">
        <mesh filename="package://cogimon_urdf/meshes/Wrist.STL" scale="0.001 -0.001 0.001"/>
      </geometry>
      <material name="dark_grey"/>
    </visual>
    <collision>
      <origin rpy="3.14159265359 0 0" xyz="0 0 0"/>
      <geometry name="LShp_collision">
        <mesh filename="package://cogimon_urdf/meshes/simple/Wrist.STL" scale="0.001 -0.001 0.001"/>
      </geometry>
    </collision>
  </link>
  <joint name="j_arm1_1" type="revolute">
    <parent link="DWYTorso"/>
    <child link="LShp"/>
    <origin rpy="0.174533 0 -0.5235988" xyz="0.0457475 0.169137 0.155126"/>
    <axis xyz="0 1 0"/>
    <limit effort="140" lower="-3.352" upper="1.603" velocity="6.283"/>
    <dynamics damping="3.0" friction="0"/>
  </joint>
  <joint name="j_arm1_2" type="revolute">
    <parent link="LShp"/>
    <child link="LShr"/>
    <origin rpy="-0.1745327 0 0" xyz="-0.09015 0.062 0"/>
    <axis xyz="1 0 0"/>
    <limit effort="140" lower="0.0" upper="3.517" velocity="6.283"/>
    <dynamics damping="3.0" friction="0"/>
  </joint>
  <joint name="j_arm1_3" type="revolute">
    <parent link="LShr"/>
    <child link="LShy"/>
    <origin rpy="0 0 0" xyz="0.09015 0 -0.21815"/>
    <axis xyz="0 0 1"/>
    <limit effort="120" lower="-2.55" upper="2.55" velocity="6.283"/>
    <dynamics damping="3.0" friction="0"/>
  </joint>
  <joint name="j_arm1_4" type="revolute">
    <parent link="LShy"/>
    <child link="LElb"/>
    <origin rpy="0 0 0" xyz="0.045 0.05515 -0.074"/>
    <axis xyz="0 1 0"/>
    <limit effort="120" lower="-2.492" upper="0.298" velocity="6.283"/>
    <dynamics damping="3.0" friction="0"/>
  </joint>
  <joint name="j_arm1_5" type="revolute">
    <parent link="LElb"/>
    <child link="LForearm"/>
    <origin rpy="0 0 0" xyz="-0.015 -0.05515 -0.095"/>
    <axis xyz="0 0 1"/>
    <limit effort="35" lower="-2.55" upper="2.55" velocity="6.283"/>
    <dynamics damping="0.03" friction="0"/>
  </joint>
  <joint name="j_arm1_6" type="revolute">
    <parent link="LForearm"/>
    <child link="LWrMot2"/>
    <origin rpy="0 0 0" xyz="0 0.049 -0.156"/>
    <axis xyz="0 1 0"/>
    <limit effort="35" lower="-1.562" upper="1.478" velocity="6.283"/>
    <dynamics damping="0.03" friction="0"/>
  </joint>
  <joint name="j_arm1_7" type="revolute">
    <parent link="LWrMot2"/>
    <child link="LWrMot3"/>
    <origin rpy="0 0 0" xyz="0 -0.049 -0.174"/>
    <axis xyz="0 0 1"/>
    <limit effort="20" lower="-2.55" upper="2.55" velocity="6.283"/>
    <dynamics damping="0.03" friction="0"/>
  </joint>
  <joint name="l_wrist_joint" type="fixed">
    <parent link="LWrMot3"/>
    <child link="l_wrist"/>
    <origin rpy="0 0 0" xyz="0 0 0"/>
  </joint>
  <link name="DWYTorso"/>
  <joint name="torso_renaming" type="fixed">
    <parent link="torso_2"/>
    <child link="DWYTorso"/>
    <origin rpy="0 0 0" xyz="0 0 -0.0385"/>
  </joint>
  <link name="arm1_1"/>
  <link name="arm1_2"/>
  <link name="arm1_3"/>
  <link name="arm1_4"/>
  <link name="arm1_5"/>
  <link name="arm1_6"/>
  <link name="arm1_7"/>
  <link name="arm1_8"/>
  <link name="arm2_1"/>
  <link name="arm2_2"/>
  <link name="arm2_3"/>
  <link name="arm2_4"/>
  <link name="arm2_5"/>
  <link name="arm2_6"/>
  <link name="arm2_7"/>
  <link name="arm2_8"/>
  <joint name="jf1" type="fixed">
    <parent link="LShp"/>
    <child link="arm1_1"/>
    <origin rpy="0 0 0" xyz="0 0 0"/>
  </joint>
  <joint name="jf2" type="fixed">
    <parent link="LShr"/>
    <child link="arm1_2"/>
    <origin rpy="0 0 0" xyz="0 0 0"/>
  </joint>
  <joint name="jf3" type="fixed">
    <parent link="LShy"/>
    <child link="arm1_3"/>
    <origin rpy="0 0 0" xyz="0 0 0"/>
  </joint>
  <joint name="jf4" type="fixed">
    <parent link="LElb"/>
    <child link="arm1_4"/>
    <origin rpy="0 0 0" xyz="0 0 0"/>
  </joint>
  <joint name="jf5" type="fixed">
    <parent link="LForearm"/>
    <child link="arm1_5"/>
    <origin rpy="0 0 0" xyz="0 0 0"/>
  </joint>
  <joint name="jf6" type="fixed">
    <parent link="LWrMot2"/>
    <child link="arm1_6"/>
    <origin rpy="0 0 0" xyz="0 0 0"/>
  </joint>
  <joint name="jf7" type="fixed">
    <parent link="LWrMot3"/>
    <child link="arm1_7"/>
    <origin rpy="0 0 0" xyz="0 0 0"/>
  </joint>
  <joint name="jf8" type="fixed">
    <parent link="arm1_7"/>
    <child link="arm1_8"/>
    <origin rpy="0 3.14159265359 -1.57079632679" xyz="0 0 -0.0405"/>
  </joint>
  <joint name="jf9" type="fixed">
    <parent link="RShp"/>
    <child link="arm2_1"/>
    <origin rpy="0 0 0" xyz="0 0 0"/>
  </joint>
  <joint name="jf10" type="fixed">
    <parent link="RShr"/>
    <child link="arm2_2"/>
    <origin rpy="0 0 0" xyz="0 0 0"/>
  </joint>
  <joint name="jf11" type="fixed">
    <parent link="RShy"/>
    <child link="arm2_3"/>
    <origin rpy="0 0 0" xyz="0 0 0"/>
  </joint>
  <joint name="jf12" type="fixed">
    <parent link="RElb"/>
    <child link="arm2_4"/>
    <origin rpy="0 0 0" xyz="0 0 0"/>
  </joint>
  <joint name="jf13" type="fixed">
    <parent link="RForearm"/>
    <child link="arm2_5"/>
    <origin rpy="0 0 0" xyz="0 0 0"/>
  </joint>
  <joint name="jf14" type="fixed">
    <parent link="RWrMot2"/>
    <child link="arm2_6"/>
    <origin rpy="0 0 0" xyz="0 0 0"/>
  </joint>
  <joint name="jf15" type="fixed">
    <parent link="RWrMot3"/>
    <child link="arm2_7"/>
    <origin rpy="0 0 0" xyz="0 0 0"/>
  </joint>
  <joint name="jf16" type="fixed">
    <parent link="arm2_7"/>
    <child link="arm2_8"/>
    <origin rpy="0 3.14159265359 -1.57079632679" xyz="0 0 -0.0405"/>
  </joint>
 
 
  <joint name="jee1" type="fixed">
      <parent link="arm1_7"/>
      <child link="ee1"/>
      <origin rpy="0 0 0" xyz="0 0 0"/>
  </joint>
  
  <link name="ee1">
    <inertial>
      <origin xyz="0 0 0"/>
      <mass value="1.130"/>
      <inertia ixx="0.0022148000000000003" ixy="0.0" ixz="-0.0" iyy="0.0022148000000000003" iyz="0.0" izz="0.0022148000000000003"/>
    </inertial>
    <visual>
      <origin rpy="0.0 0.0 0.0" xyz="0.0 0.0 0.0"/>
      <geometry>
        <sphere radius="0.07"/> 
      </geometry>
      <material name="dark_grey"/>
    </visual>
   </link>
  

   <joint name="jee2" type="fixed">
      <parent link="arm2_7"/>
      <child link="ee2"/>
      <origin rpy="0 0 0" xyz="0 0 0"/>
  </joint>
  
  <link name="ee2">
    <inertial>
      <origin xyz="0 0 0"/>
      <mass value="1.130"/>
      <inertia ixx="0.0022148000000000003" ixy="0.0" ixz="-0.0" iyy="0.0022148000000000003" iyz="0.0" izz="0.0022148000000000003"/>
    </inertial>
    <visual>
      <origin rpy="0.0 0.0 0.0" xyz="0.0 0.0 0.0"/>
      <geometry>
        <sphere radius="0.07"/> 
      </geometry>
      <material name="dark_grey"/>
    </visual>
  </link>

  
   <!-- /joints -->
  <!-- /end-effector -->
  <!-- /arms -->
  <link name="hip1_1">
    <inertial>
      <origin xyz="0.010214199 -0.018348359 0.038090987"/>
      <mass value="1.9194403"/>
      <!-- org: 2 -->
      <inertia ixx="0.0047439572" ixy="0.0005747047" ixz="-0.0003784138" iyy="0.0040551878" iyz="0.0007407508" izz="0.0034146219"/>
      <!-- <inertia ixx="0.01" ixy="0.01" ixz="0.01" iyy="0.01" iyz="0.01" izz="0.01"/> -->
    </inertial>
    <visual>
      <origin rpy="0.0 0.0 4.15579005089" xyz="0.0 0.0 0.0"/>
      <geometry>
        <mesh filename="package://centauro/centauro_urdf/meshes/simplified/hip-yaw.stl" scale="0.001 0.001 0.001"/>
      </geometry>
      <material name="dark_grey"/>
    </visual>
    <collision>
      <origin rpy="0.0 0.0 4.15579005089" xyz="0.0 0.0 0.0"/>
      <geometry>
        <mesh filename="package://centauro/centauro_urdf/meshes/convex_hull/hip-yaw.stl" scale="0.001 0.001 0.001"/>
      </geometry>
    </collision>
  </link>
  <link name="hip2_1">
    <inertial>
      <origin xyz="2.57966e-05 0.1810266 0.085669756"/>
      <mass value="2.7264471"/>
      <!-- org: 4.5 -->
      <inertia ixx="0.04851869" ixy="-4.11894e-05" ixz="-1.68778e-05" iyy="0.004242055" iyz="0.0032243188" izz="0.04825583"/>
      <!-- <inertia ixx="0.01" ixy="0.01" ixz="0.01" iyy="0.01" iyz="0.01" izz="0.01"/> -->
    </inertial>
    <visual>
      <origin rpy="0.0 0.0 0.0" xyz="0.0 0.0 0.0"/>
      <geometry>
        <mesh filename="package://centauro/centauro_urdf/meshes/simplified/hip-pitch.stl" scale="0.001 0.001 0.001"/>
      </geometry>
    </visual>
    <collision>
      <origin rpy="0.0 0.0 0.0" xyz="0.0 0.0 0.0"/>
      <geometry>
        <mesh filename="package://centauro/centauro_urdf/meshes/convex_hull/hip-pitch.stl" scale="0.001 0.001 0.001"/>
      </geometry>
    </collision>
  </link>
  <link name="knee_1">
    <inertial>
      <origin xyz="0.10881667 0.0001089081 -0.022638996"/>
      <mass value="1.9356754"/>
      <!-- org: 3.5, foot un modeled-->
      <inertia ixx="0.0030534242" ixy="-4.22079e-05" ixz="0.0013679297" iyy="0.019603321" iyz="6.9941e-06" izz="0.019849817"/>
      <!--  <inertia ixx="0.01" ixy="0.01" ixz="0.01" iyy="0.01" iyz="0.01" izz="0.01"/>  -->
    </inertial>
    <visual>
      <origin rpy="0.0 0.0 0.0" xyz="0.0 0.0 0.0"/>
      <geometry>
        <mesh filename="package://centauro/centauro_urdf/meshes/simplified/knee.stl" scale="0.001 0.001 0.001"/>
      </geometry>
      <material name="dark_grey"/>
    </visual>
    <collision>
      <origin rpy="0.0 0.0 0.0" xyz="0.0 0.0 0.0"/>
      <geometry>
        <mesh filename="package://centauro/centauro_urdf/meshes/convex_hull/knee.stl" scale="0.001 0.001 0.001"/>
      </geometry>
    </collision>
  </link>
  <link name="ankle1_1">
    <inertial>
      <origin xyz="0.032137318 9.73572e-05 -0.0044222206"/>
      <mass value="1.2380744"/>
      <!-- org: 3.5, foot un modeled-->
      <inertia ixx="0.0015610452" ixy="3.30597e-05" ixz="-0.0001314174" iyy="0.0037423211" iyz="-2.12589e-05" izz="0.0038312442"/>
      <!--  <inertia ixx="0.01" ixy="0.01" ixz="0.01" iyy="0.01" iyz="0.01" izz="0.01"/>  -->
    </inertial>
    <visual>
      <origin rpy="0.0 0.0 0.0" xyz="0.0 0.0 0.0"/>
      <geometry>
        <mesh filename="package://centauro/centauro_urdf/meshes/simplified/ankle-pitch.stl" scale="0.001 0.001 0.001"/>
      </geometry>
    </visual>
    <collision>
      <origin rpy="0.0 0.0 0.0" xyz="0.0 0.0 0.0"/>
      <geometry>
        <mesh filename="package://centauro/centauro_urdf/meshes/convex_hull/ankle-pitch.stl" scale="0.001 0.001 0.001"/>
      </geometry>
    </collision>
  </link>
  <link name="ankle2_1">
    <inertial>
      <origin xyz="0.0004435803 0.0004389911 0.19392092"/>
      <mass value="1.1565926"/>
      <!-- org: 3.5, foot un modeled-->
      <inertia ixx="0.0049019475" ixy="4.3032e-06" ixz="3.46491e-05" iyy="0.0038724162" iyz="1.7099e-05" izz="0.0021783198"/>
    </inertial>
    <visual>
      <origin rpy="0.0 0.0 0.0" xyz="0.0 0.0 0.0"/>
      <geometry>
        <mesh filename="package://centauro/centauro_urdf/meshes/simplified/ankle-yaw.stl" scale="0.001 0.001 0.001"/>
      </geometry>
      <material name="dark_grey"/>
    </visual>
    <collision>
      <origin rpy="0.0 0.0 0.0" xyz="0.0 0.0 0.0"/>
      <geometry>
        <mesh filename="package://centauro/centauro_urdf/meshes/convex_hull/ankle-yaw.stl" scale="0.001 0.001 0.001"/>
      </geometry>
    </collision>
  </link>
  <link name="wheel_1">
    <inertial>
      <origin xyz="0.0 0.0 0.0024271906"/>
      <mass value="1.7289003"/>
      <!-- org: 3.5, foot un modeled-->
      <inertia ixx="0.0046864297" ixy="0.0" ixz="0.0" iyy="0.0046713489" iyz="0.0" izz="0.0053126029"/>
    </inertial>
    <visual>
      <origin rpy="0.0 0.0 0.0" xyz="0.0 0.0 0.0"/>
      <geometry>
        <mesh filename="package://centauro/centauro_urdf/meshes/simplified/wheel.stl" scale="0.001 0.001 0.001"/>
      </geometry>
      <material name="black"/>
    </visual>
    <collision>
      <origin rpy="0.0 0.0 0.0" xyz="0.0 0.0 0.0"/>
      <geometry>
        <mesh filename="package://centauro/centauro_urdf/meshes/convex_hull/wheel.stl" scale="0.001 0.001 0.001"/>
      </geometry>
    </collision>
  </link>
  <joint name="hip_yaw_1" type="revolute">
    <parent link="pelvis"/>
    <child link="hip1_1"/>
    <origin rpy="3.14159265359 0.0 0.50709869865" xyz="0.25 0.125 -0.0566"/>
    <axis xyz="0 0 1"/>
    <limit effort="304" lower="-2.00" upper="2.48" velocity="8.8"/>
  </joint>
  <joint name="hip_pitch_1" type="revolute">
    <parent link="hip1_1"/>
    <child link="hip2_1"/>
    <origin rpy="1.57079632679 0.0 0.50709869865" xyz="0.0 0.0 0.059"/>
    <axis xyz="0 0 1"/>
    <limit effort="304" lower="-2.07" upper="2.07" velocity="8.8"/>
  </joint>
  <joint name="knee_pitch_1" type="revolute">
    <parent link="hip2_1"/>
    <child link="knee_1"/>
    <origin rpy="3.14159265359 0.0 1.57079632679" xyz="0.0 0.3 -0.0036"/>
    <axis xyz="0 0 1"/>
    <limit effort="304" lower="-2.61799388" upper="2.61799388" velocity="8.8"/>
  </joint>
  <joint name="ankle_pitch_1" type="revolute">
    <parent link="knee_1"/>
    <child link="ankle1_1"/>
    <origin rpy="3.14159265359 0.0 0.0" xyz="0.2 0.0 -0.10015"/>
    <axis xyz="0 0 1"/>
    <limit effort="147" lower="-2.61799388" upper="2.61799388" velocity="8.1"/>
  </joint>
  <joint name="ankle_yaw_1" type="revolute">
    <parent link="ankle1_1"/>
    <child link="ankle2_1"/>
    <origin rpy="1.57079632679 0.0 1.57079632679" xyz="0.0 0.0 0.0"/>
    <axis xyz="0 0 1"/>
    <limit effort="35" lower="-2.5" upper="2.5" velocity="20.0"/>
  </joint>
  <joint name="j_wheel_1" type="continuous">
    <parent link="ankle2_1"/>
    <child link="wheel_1"/>
    <origin rpy="1.57079632679 0.0 0.0" xyz="0.0 0.00085 0.235"/>
    <axis xyz="0 0 -1"/>
    <limit effort="35" velocity="20.0" lower="-1000000000000000" upper="1000000000000000"/>
  </joint>
  <transmission name="t_hip_yaw_1">
    <type> transmission_interface/SimpleTransmission</type>
    <joint name="hip_yaw_1">
      <hardwareInterface>EffortJointInterface</hardwareInterface>
    </joint>
    <actuator name="motor_hip_yaw_1">
      <hardwareInterface>EffortJointInterface</hardwareInterface>
      <machanicalReduction>1</machanicalReduction>
    </actuator>
    <robotNamespace>/centauro</robotNamespace>
  </transmission>
  <transmission name="t_hip_pitch_1">
    <type> transmission_interface/SimpleTransmission</type>
    <joint name="hip_pitch_1">
      <hardwareInterface>EffortJointInterface</hardwareInterface>
    </joint>
    <actuator name="motor_hip_pitch_1">
      <hardwareInterface>EffortJointInterface</hardwareInterface>
      <machanicalReduction>1</machanicalReduction>
    </actuator>
    <robotNamespace>/centauro</robotNamespace>
  </transmission>
  <transmission name="t_knee_pitch_1">
    <type> transmission_interface/SimpleTransmission</type>
    <joint name="knee_pitch_1">
      <hardwareInterface>EffortJointInterface</hardwareInterface>
    </joint>
    <actuator name="motor_knee_pitch_1">
      <hardwareInterface>EffortJointInterface</hardwareInterface>
      <machanicalReduction>1</machanicalReduction>
    </actuator>
    <robotNamespace>/centauro</robotNamespace>
  </transmission>
  <transmission name="t_ankle_pitch_1">
    <type> transmission_interface/SimpleTransmission</type>
    <joint name="ankle_pitch_1">
      <hardwareInterface>EffortJointInterface</hardwareInterface>
    </joint>
    <actuator name="motor_ankle_pitch_1">
      <hardwareInterface>EffortJointInterface</hardwareInterface>
      <machanicalReduction>1</machanicalReduction>
    </actuator>
    <robotNamespace>/centauro</robotNamespace>
  </transmission>
  <transmission name="t_ankle_yaw_1">
    <type> transmission_interface/SimpleTransmission</type>
    <joint name="ankle_yaw_1">
      <hardwareInterface>EffortJointInterface</hardwareInterface>
    </joint>
    <actuator name="motor_ankle_yaw_1">
      <hardwareInterface>EffortJointInterface</hardwareInterface>
      <machanicalReduction>1</machanicalReduction>
    </actuator>
    <robotNamespace>/centauro</robotNamespace>
  </transmission>
  <transmission name="t_j_wheel_1">
    <type> transmission_interface/SimpleTransmission</type>
    <joint name="j_wheel_1">
      <hardwareInterface>EffortJointInterface</hardwareInterface>
    </joint>
    <actuator name="motor_j_wheel_1">
      <hardwareInterface>EffortJointInterface</hardwareInterface>
      <machanicalReduction>1</machanicalReduction>
    </actuator>
    <robotNamespace>/centauro</robotNamespace>
  </transmission>
  <!-- /actuators -->
  <link name="hip1_2">
    <inertial>
      <origin xyz="0.010214199 0.018348359 0.038090987"/>
      <mass value="1.9194403"/>
      <!-- org: 2 -->
      <inertia ixx="0.0047439572" ixy="-0.0005747047" ixz="-0.0003784138" iyy="0.0040551878" iyz="-0.0007407508" izz="0.0034146219"/>
      <!-- <inertia ixx="0.01" ixy="0.01" ixz="0.01" iyy="0.01" iyz="0.01" izz="0.01"/> -->
    </inertial>
    <visual>
      <origin rpy="0.0 0.0 0.0" xyz="0.0 0.0 0.0"/>
      <geometry>
        <mesh filename="package://centauro/centauro_urdf/meshes/simplified/hip-yaw.stl" scale="0.001 0.001 0.001"/>
      </geometry>
      <material name="dark_grey"/>
    </visual>
    <collision>
      <origin rpy="0.0 0.0 0.0" xyz="0.0 0.0 0.0"/>
      <geometry>
        <mesh filename="package://centauro/centauro_urdf/meshes/convex_hull/hip-yaw.stl" scale="0.001 0.001 0.001"/>
      </geometry>
    </collision>
  </link>
  <link name="hip2_2">
    <inertial>
      <origin xyz="2.57966e-05 0.1810266 0.085669756"/>
      <mass value="2.7264471"/>
      <!-- org: 4.5 -->
      <inertia ixx="0.04851869" ixy="-4.11894e-05" ixz="-1.68778e-05" iyy="0.004242055" iyz="0.0032243188" izz="0.04825583"/>
      <!-- <inertia ixx="0.01" ixy="0.01" ixz="0.01" iyy="0.01" iyz="0.01" izz="0.01"/> -->
    </inertial>
    <visual>
      <origin rpy="0.0 0.0 0.0" xyz="0.0 0.0 0.0"/>
      <geometry>
        <mesh filename="package://centauro/centauro_urdf/meshes/simplified/hip-pitch.stl" scale="0.001 0.001 0.001"/>
      </geometry>
    </visual>
    <collision>
      <origin rpy="0.0 0.0 0.0" xyz="0.0 0.0 0.0"/>
      <geometry>
        <mesh filename="package://centauro/centauro_urdf/meshes/convex_hull/hip-pitch.stl" scale="0.001 0.001 0.001"/>
      </geometry>
    </collision>
  </link>
  <link name="knee_2">
    <inertial>
      <origin xyz="0.10881667 0.0001089081 -0.022638996"/>
      <mass value="1.9356754"/>
      <!-- org: 3.5, foot un modeled-->
      <inertia ixx="0.0030534242" ixy="-4.22079e-05" ixz="0.0013679297" iyy="0.019603321" iyz="6.9941e-06" izz="0.019849817"/>
      <!--  <inertia ixx="0.01" ixy="0.01" ixz="0.01" iyy="0.01" iyz="0.01" izz="0.01"/>  -->
    </inertial>
    <visual>
      <origin rpy="0.0 0.0 0.0" xyz="0.0 0.0 0.0"/>
      <geometry>
        <mesh filename="package://centauro/centauro_urdf/meshes/simplified/knee.stl" scale="0.001 0.001 0.001"/>
      </geometry>
      <material name="dark_grey"/>
    </visual>
    <collision>
      <origin rpy="0.0 0.0 0.0" xyz="0.0 0.0 0.0"/>
      <geometry>
        <mesh filename="package://centauro/centauro_urdf/meshes/convex_hull/knee.stl" scale="0.001 0.001 0.001"/>
      </geometry>
    </collision>
  </link>
  <link name="ankle1_2">
    <inertial>
      <origin xyz="0.032137318 9.73572e-05 -0.0044222206"/>
      <mass value="1.2380744"/>
      <!-- org: 3.5, foot un modeled-->
      <inertia ixx="0.0015610452" ixy="3.30597e-05" ixz="-0.0001314174" iyy="0.0037423211" iyz="-2.12589e-05" izz="0.0038312442"/>
      <!--  <inertia ixx="0.01" ixy="0.01" ixz="0.01" iyy="0.01" iyz="0.01" izz="0.01"/>  -->
    </inertial>
    <visual>
      <origin rpy="0.0 0.0 0.0" xyz="0.0 0.0 0.0"/>
      <geometry>
        <mesh filename="package://centauro/centauro_urdf/meshes/simplified/ankle-pitch.stl" scale="0.001 0.001 0.001"/>
      </geometry>
    </visual>
    <collision>
      <origin rpy="0.0 0.0 0.0" xyz="0.0 0.0 0.0"/>
      <geometry>
        <mesh filename="package://centauro/centauro_urdf/meshes/convex_hull/ankle-pitch.stl" scale="0.001 0.001 0.001"/>
      </geometry>
    </collision>
  </link>
  <link name="ankle2_2">
    <inertial>
      <origin xyz="0.0004435803 0.0004389911 0.19392092"/>
      <mass value="1.1565926"/>
      <!-- org: 3.5, foot un modeled-->
      <inertia ixx="0.0049019475" ixy="4.3032e-06" ixz="3.46491e-05" iyy="0.0038724162" iyz="1.7099e-05" izz="0.0021783198"/>
    </inertial>
    <visual>
      <origin rpy="0.0 0.0 0.0" xyz="0.0 0.0 0.0"/>
      <geometry>
        <mesh filename="package://centauro/centauro_urdf/meshes/simplified/ankle-yaw.stl" scale="0.001 0.001 0.001"/>
      </geometry>
      <material name="dark_grey"/>
    </visual>
    <collision>
      <origin rpy="0.0 0.0 0.0" xyz="0.0 0.0 0.0"/>
      <geometry>
        <mesh filename="package://centauro/centauro_urdf/meshes/convex_hull/ankle-yaw.stl" scale="0.001 0.001 0.001"/>
      </geometry>
    </collision>
  </link>
  <link name="wheel_2">
    <inertial>
      <origin xyz="0.0 0.0 0.0024271906"/>
      <mass value="1.7289003"/>
      <!-- org: 3.5, foot un modeled-->
      <inertia ixx="0.0046864297" ixy="0.0" ixz="0.0" iyy="0.0046713489" iyz="0.0" izz="0.0053126029"/>
    </inertial>
    <visual>
      <origin rpy="0.0 0.0 0.0" xyz="0.0 0.0 0.0"/>
      <geometry>
        <mesh filename="package://centauro/centauro_urdf/meshes/simplified/wheel.stl" scale="0.001 0.001 0.001"/>
      </geometry>
      <material name="black"/>
    </visual>
    <collision>
      <origin rpy="0.0 0.0 0.0" xyz="0.0 0.0 0.0"/>
      <geometry>
        <mesh filename="package://centauro/centauro_urdf/meshes/convex_hull/wheel.stl" scale="0.001 0.001 0.001"/>
      </geometry>
    </collision>
  </link>
  <joint name="hip_yaw_2" type="revolute">
    <parent link="pelvis"/>
    <child link="hip1_2"/>
    <origin rpy="3.14159265359 0.0 -0.50709869865" xyz="0.25 -0.125 -0.0566"/>
    <axis xyz="0 0 1"/>
    <limit effort="304" lower="-2.48" upper="2.00" velocity="8.8"/>
  </joint>
  <joint name="hip_pitch_2" type="revolute">
    <parent link="hip1_2"/>
    <child link="hip2_2"/>
    <origin rpy="1.57079632679 0.0 2.63449395494" xyz="0.0 0.0 0.059"/>
    <axis xyz="0 0 1"/>
    <limit effort="304" lower="-2.06" upper="2.09439510" velocity="8.8"/>
  </joint>
  <joint name="knee_pitch_2" type="revolute">
    <parent link="hip2_2"/>
    <child link="knee_2"/>
    <origin rpy="3.14159265359 0.0 1.57079632679" xyz="0.0 0.3 -0.0036"/>
    <axis xyz="0 0 1"/>
    <limit effort="304" lower="-2.61799388" upper="2.61799388" velocity="8.8"/>
  </joint>
  <joint name="ankle_pitch_2" type="revolute">
    <parent link="knee_2"/>
    <child link="ankle1_2"/>
    <origin rpy="3.14159265359 0.0 0.0" xyz="0.2 0.0 -0.10015"/>
    <axis xyz="0 0 1"/>
    <limit effort="147" lower="-2.61799388" upper="2.61799388" velocity="8.1"/>
  </joint>
  <joint name="ankle_yaw_2" type="revolute">
    <parent link="ankle1_2"/>
    <child link="ankle2_2"/>
    <origin rpy="1.57079632679 0.0 1.57079632679" xyz="0.0 0.0 0.0"/>
    <axis xyz="0 0 1"/>
    <limit effort="35" lower="-2.5" upper="2.5" velocity="20.0"/>
  </joint>
  <joint name="j_wheel_2" type="continuous">
    <parent link="ankle2_2"/>
    <child link="wheel_2"/>
    <origin rpy="1.57079632679 0.0 0.0" xyz="0.0 0.00085 0.235"/>
    <axis xyz="0 0 -1"/>
    <limit effort="35" velocity="20.0" lower="-1000000000000000" upper="1000000000000000"/>
  </joint>
  <transmission name="t_hip_yaw_2">
    <type> transmission_interface/SimpleTransmission</type>
    <joint name="hip_yaw_2">
      <hardwareInterface>EffortJointInterface</hardwareInterface>
    </joint>
    <actuator name="motor_hip_yaw_2">
      <hardwareInterface>EffortJointInterface</hardwareInterface>
      <machanicalReduction>1</machanicalReduction>
    </actuator>
    <robotNamespace>/centauro</robotNamespace>
  </transmission>
  <transmission name="t_hip_pitch_2">
    <type> transmission_interface/SimpleTransmission</type>
    <joint name="hip_pitch_2">
      <hardwareInterface>EffortJointInterface</hardwareInterface>
    </joint>
    <actuator name="motor_hip_pitch_2">
      <hardwareInterface>EffortJointInterface</hardwareInterface>
      <machanicalReduction>1</machanicalReduction>
    </actuator>
    <robotNamespace>/centauro</robotNamespace>
  </transmission>
  <transmission name="t_knee_pitch_2">
    <type> transmission_interface/SimpleTransmission</type>
    <joint name="knee_pitch_2">
      <hardwareInterface>EffortJointInterface</hardwareInterface>
    </joint>
    <actuator name="motor_knee_pitch_2">
      <hardwareInterface>EffortJointInterface</hardwareInterface>
      <machanicalReduction>1</machanicalReduction>
    </actuator>
    <robotNamespace>/centauro</robotNamespace>
  </transmission>
  <transmission name="t_ankle_pitch_2">
    <type> transmission_interface/SimpleTransmission</type>
    <joint name="ankle_pitch_2">
      <hardwareInterface>EffortJointInterface</hardwareInterface>
    </joint>
    <actuator name="motor_ankle_pitch_2">
      <hardwareInterface>EffortJointInterface</hardwareInterface>
      <machanicalReduction>1</machanicalReduction>
    </actuator>
    <robotNamespace>/centauro</robotNamespace>
  </transmission>
  <transmission name="t_ankle_yaw_2">
    <type> transmission_interface/SimpleTransmission</type>
    <joint name="ankle_yaw_2">
      <hardwareInterface>EffortJointInterface</hardwareInterface>
    </joint>
    <actuator name="motor_ankle_yaw_2">
      <hardwareInterface>EffortJointInterface</hardwareInterface>
      <machanicalReduction>1</machanicalReduction>
    </actuator>
    <robotNamespace>/centauro</robotNamespace>
  </transmission>
  <transmission name="t_j_wheel_2">
    <type> transmission_interface/SimpleTransmission</type>
    <joint name="j_wheel_2">
      <hardwareInterface>EffortJointInterface</hardwareInterface>
    </joint>
    <actuator name="motor_j_wheel_2">
      <hardwareInterface>EffortJointInterface</hardwareInterface>
      <machanicalReduction>1</machanicalReduction>
    </actuator>
    <robotNamespace>/centauro</robotNamespace>
  </transmission>
  <!-- /actuators -->
  <link name="hip1_3">
    <inertial>
      <origin xyz="0.010214199 0.018348359 0.038090987"/>
      <mass value="1.9194403"/>
      <!-- org: 2 -->
      <inertia ixx="0.0047439572" ixy="-0.0005747047" ixz="-0.0003784138" iyy="0.0040551878" iyz="-0.0007407508" izz="0.0034146219"/>
      <!-- <inertia ixx="0.01" ixy="0.01" ixz="0.01" iyy="0.01" iyz="0.01" izz="0.01"/> -->
    </inertial>
    <visual>
      <origin rpy="0.0 0.0 0.0" xyz="0.0 0.0 0.0"/>
      <geometry>
        <mesh filename="package://centauro/centauro_urdf/meshes/simplified/hip-yaw.stl" scale="0.001 0.001 0.001"/>
      </geometry>
      <material name="dark_grey"/>
    </visual>
    <collision>
      <origin rpy="0.0 0.0 0.0" xyz="0.0 0.0 0.0"/>
      <geometry>
        <mesh filename="package://centauro/centauro_urdf/meshes/convex_hull/hip-yaw.stl" scale="0.001 0.001 0.001"/>
      </geometry>
    </collision>
  </link>
  <link name="hip2_3">
    <inertial>
      <origin xyz="2.57966e-05 0.1810266 0.085669756"/>
      <mass value="2.7264471"/>
      <!-- org: 4.5 -->
      <inertia ixx="0.04851869" ixy="-4.11894e-05" ixz="-1.68778e-05" iyy="0.004242055" iyz="0.0032243188" izz="0.04825583"/>
      <!-- <inertia ixx="0.01" ixy="0.01" ixz="0.01" iyy="0.01" iyz="0.01" izz="0.01"/> -->
    </inertial>
    <visual>
      <origin rpy="0.0 0.0 0.0" xyz="0.0 0.0 0.0"/>
      <geometry>
        <mesh filename="package://centauro/centauro_urdf/meshes/simplified/hip-pitch.stl" scale="0.001 0.001 0.001"/>
      </geometry>
    </visual>
    <collision>
      <origin rpy="0.0 0.0 0.0" xyz="0.0 0.0 0.0"/>
      <geometry>
        <mesh filename="package://centauro/centauro_urdf/meshes/convex_hull/hip-pitch.stl" scale="0.001 0.001 0.001"/>
      </geometry>
    </collision>
  </link>
  <link name="knee_3">
    <inertial>
      <origin xyz="0.10881667 0.0001089081 -0.022638996"/>
      <mass value="1.9356754"/>
      <!-- org: 3.5, foot un modeled-->
      <inertia ixx="0.0030534242" ixy="-4.22079e-05" ixz="0.0013679297" iyy="0.019603321" iyz="6.9941e-06" izz="0.019849817"/>
      <!--  <inertia ixx="0.01" ixy="0.01" ixz="0.01" iyy="0.01" iyz="0.01" izz="0.01"/>  -->
    </inertial>
    <visual>
      <origin rpy="0.0 0.0 0.0" xyz="0.0 0.0 0.0"/>
      <geometry>
        <mesh filename="package://centauro/centauro_urdf/meshes/simplified/knee.stl" scale="0.001 0.001 0.001"/>
      </geometry>
      <material name="dark_grey"/>
    </visual>
    <collision>
      <origin rpy="0.0 0.0 0.0" xyz="0.0 0.0 0.0"/>
      <geometry>
        <mesh filename="package://centauro/centauro_urdf/meshes/convex_hull/knee.stl" scale="0.001 0.001 0.001"/>
      </geometry>
    </collision>
  </link>
  <link name="ankle1_3">
    <inertial>
      <origin xyz="0.032137318 9.73572e-05 -0.0044222206"/>
      <mass value="1.2380744"/>
      <!-- org: 3.5, foot un modeled-->
      <inertia ixx="0.0015610452" ixy="3.30597e-05" ixz="-0.0001314174" iyy="0.0037423211" iyz="-2.12589e-05" izz="0.0038312442"/>
      <!--  <inertia ixx="0.01" ixy="0.01" ixz="0.01" iyy="0.01" iyz="0.01" izz="0.01"/>  -->
    </inertial>
    <visual>
      <origin rpy="0.0 0.0 0.0" xyz="0.0 0.0 0.0"/>
      <geometry>
        <mesh filename="package://centauro/centauro_urdf/meshes/simplified/ankle-pitch.stl" scale="0.001 0.001 0.001"/>
      </geometry>
    </visual>
    <collision>
      <origin rpy="0.0 0.0 0.0" xyz="0.0 0.0 0.0"/>
      <geometry>
        <mesh filename="package://centauro/centauro_urdf/meshes/convex_hull/ankle-pitch.stl" scale="0.001 0.001 0.001"/>
      </geometry>
    </collision>
  </link>
  <link name="ankle2_3">
    <inertial>
      <origin xyz="0.0004435803 0.0004389911 0.19392092"/>
      <mass value="1.1565926"/>
      <!-- org: 3.5, foot un modeled-->
      <inertia ixx="0.0049019475" ixy="4.3032e-06" ixz="3.46491e-05" iyy="0.0038724162" iyz="1.7099e-05" izz="0.0021783198"/>
    </inertial>
    <visual>
      <origin rpy="0.0 0.0 0.0" xyz="0.0 0.0 0.0"/>
      <geometry>
        <mesh filename="package://centauro/centauro_urdf/meshes/simplified/ankle-yaw.stl" scale="0.001 0.001 0.001"/>
      </geometry>
      <material name="dark_grey"/>
    </visual>
    <collision>
      <origin rpy="0.0 0.0 0.0" xyz="0.0 0.0 0.0"/>
      <geometry>
        <mesh filename="package://centauro/centauro_urdf/meshes/convex_hull/ankle-yaw.stl" scale="0.001 0.001 0.001"/>
      </geometry>
    </collision>
  </link>
  <link name="wheel_3">
    <inertial>
      <origin xyz="0.0 0.0 0.0024271906"/>
      <mass value="1.7289003"/>
      <!-- org: 3.5, foot un modeled-->
      <inertia ixx="0.0046864297" ixy="0.0" ixz="0.0" iyy="0.0046713489" iyz="0.0" izz="0.0053126029"/>
    </inertial>
    <visual>
      <origin rpy="0.0 0.0 0.0" xyz="0.0 0.0 0.0"/>
      <geometry>
        <mesh filename="package://centauro/centauro_urdf/meshes/simplified/wheel.stl" scale="0.001 0.001 0.001"/>
      </geometry>
      <material name="black"/>
    </visual>
    <collision>
      <origin rpy="0.0 0.0 0.0" xyz="0.0 0.0 0.0"/>
      <geometry>
        <mesh filename="package://centauro/centauro_urdf/meshes/convex_hull/wheel.stl" scale="0.001 0.001 0.001"/>
      </geometry>
    </collision>
  </link>
  <joint name="hip_yaw_3" type="revolute">
    <parent link="pelvis"/>
    <child link="hip1_3"/>
    <origin rpy="3.14159265359 0.0 2.63449395494" xyz="-0.25 0.125 -0.0566"/>
    <axis xyz="0 0 1"/>
    <limit effort="304" lower="-2.48" upper="2.0" velocity="8.8"/>
  </joint>
  <joint name="hip_pitch_3" type="revolute">
    <parent link="hip1_3"/>
    <child link="hip2_3"/>
    <origin rpy="1.57079632679 0.0 2.63449395494" xyz="0.0 0.0 0.059"/>
    <axis xyz="0 0 1"/>
    <limit effort="304" lower="-2.07" upper="2.09439510" velocity="8.8"/>
  </joint>
  <joint name="knee_pitch_3" type="revolute">
    <parent link="hip2_3"/>
    <child link="knee_3"/>
    <origin rpy="3.14159265359 0.0 1.57079632679" xyz="0.0 0.3 -0.0036"/>
    <axis xyz="0 0 1"/>
    <limit effort="304" lower="-2.61799388" upper="2.61799388" velocity="8.8"/>
  </joint>
  <joint name="ankle_pitch_3" type="revolute">
    <parent link="knee_3"/>
    <child link="ankle1_3"/>
    <origin rpy="3.14159265359 0.0 0.0" xyz="0.2 0.0 -0.10015"/>
    <axis xyz="0 0 1"/>
    <limit effort="147" lower="-2.61799388" upper="2.61799388" velocity="8.1"/>
  </joint>
  <joint name="ankle_yaw_3" type="revolute">
    <parent link="ankle1_3"/>
    <child link="ankle2_3"/>
    <origin rpy="1.57079632679 0.0 1.57079632679" xyz="0.0 0.0 0.0"/>
    <axis xyz="0 0 1"/>
    <limit effort="35" lower="-2.5" upper="2.5" velocity="20.0"/>
  </joint>
  <joint name="j_wheel_3" type="continuous">
    <parent link="ankle2_3"/>
    <child link="wheel_3"/>
    <origin rpy="1.57079632679 0.0 0.0" xyz="0.0 0.00085 0.235"/>
    <axis xyz="0 0 -1"/>
    <limit effort="35" velocity="20.0" lower="-1000000000000000" upper="1000000000000000"/>
  </joint>
  <transmission name="t_hip_yaw_3">
    <type> transmission_interface/SimpleTransmission</type>
    <joint name="hip_yaw_3">
      <hardwareInterface>EffortJointInterface</hardwareInterface>
    </joint>
    <actuator name="motor_hip_yaw_3">
      <hardwareInterface>EffortJointInterface</hardwareInterface>
      <machanicalReduction>1</machanicalReduction>
    </actuator>
    <robotNamespace>/centauro</robotNamespace>
  </transmission>
  <transmission name="t_hip_pitch_3">
    <type> transmission_interface/SimpleTransmission</type>
    <joint name="hip_pitch_3">
      <hardwareInterface>EffortJointInterface</hardwareInterface>
    </joint>
    <actuator name="motor_hip_pitch_3">
      <hardwareInterface>EffortJointInterface</hardwareInterface>
      <machanicalReduction>1</machanicalReduction>
    </actuator>
    <robotNamespace>/centauro</robotNamespace>
  </transmission>
  <transmission name="t_knee_pitch_3">
    <type> transmission_interface/SimpleTransmission</type>
    <joint name="knee_pitch_3">
      <hardwareInterface>EffortJointInterface</hardwareInterface>
    </joint>
    <actuator name="motor_knee_pitch_3">
      <hardwareInterface>EffortJointInterface</hardwareInterface>
      <machanicalReduction>1</machanicalReduction>
    </actuator>
    <robotNamespace>/centauro</robotNamespace>
  </transmission>
  <transmission name="t_ankle_pitch_3">
    <type> transmission_interface/SimpleTransmission</type>
    <joint name="ankle_pitch_3">
      <hardwareInterface>EffortJointInterface</hardwareInterface>
    </joint>
    <actuator name="motor_ankle_pitch_3">
      <hardwareInterface>EffortJointInterface</hardwareInterface>
      <machanicalReduction>1</machanicalReduction>
    </actuator>
    <robotNamespace>/centauro</robotNamespace>
  </transmission>
  <transmission name="t_ankle_yaw_3">
    <type> transmission_interface/SimpleTransmission</type>
    <joint name="ankle_yaw_3">
      <hardwareInterface>EffortJointInterface</hardwareInterface>
    </joint>
    <actuator name="motor_ankle_yaw_3">
      <hardwareInterface>EffortJointInterface</hardwareInterface>
      <machanicalReduction>1</machanicalReduction>
    </actuator>
    <robotNamespace>/centauro</robotNamespace>
  </transmission>
  <transmission name="t_j_wheel_3">
    <type> transmission_interface/SimpleTransmission</type>
    <joint name="j_wheel_3">
      <hardwareInterface>EffortJointInterface</hardwareInterface>
    </joint>
    <actuator name="motor_j_wheel_3">
      <hardwareInterface>EffortJointInterface</hardwareInterface>
      <machanicalReduction>1</machanicalReduction>
    </actuator>
    <robotNamespace>/centauro</robotNamespace>
  </transmission>
  <!-- /actuators -->
  <link name="hip1_4">
    <inertial>
      <origin xyz="0.010214199 -0.018348359 0.038090987"/>
      <mass value="1.9194403"/>
      <!-- org: 2 -->
      <inertia ixx="0.0047439572" ixy="0.0005747047" ixz="-0.0003784138" iyy="0.0040551878" iyz="0.0007407508" izz="0.0034146219"/>
      <!-- <inertia ixx="0.01" ixy="0.01" ixz="0.01" iyy="0.01" iyz="0.01" izz="0.01"/> -->
    </inertial>
    <visual>
      <origin rpy="0.0 0.0 4.15579005089" xyz="0.0 0.0 0.0"/>
      <geometry>
        <mesh filename="package://centauro/centauro_urdf/meshes/simplified/hip-yaw.stl" scale="0.001 0.001 0.001"/>
      </geometry>
      <material name="dark_grey"/>
    </visual>
    <collision>
      <origin rpy="0.0 0.0 4.15579005089" xyz="0.0 0.0 0.0"/>
      <geometry>
        <mesh filename="package://centauro/centauro_urdf/meshes/convex_hull/hip-yaw.stl" scale="0.001 0.001 0.001"/>
      </geometry>
    </collision>
  </link>
  <link name="hip2_4">
    <inertial>
      <origin xyz="2.57966e-05 0.1810266 0.085669756"/>
      <mass value="2.7264471"/>
      <!-- org: 4.5 -->
      <inertia ixx="0.04851869" ixy="-4.11894e-05" ixz="-1.68778e-05" iyy="0.004242055" iyz="0.0032243188" izz="0.04825583"/>
      <!-- <inertia ixx="0.01" ixy="0.01" ixz="0.01" iyy="0.01" iyz="0.01" izz="0.01"/> -->
    </inertial>
    <visual>
      <origin rpy="0.0 0.0 0.0" xyz="0.0 0.0 0.0"/>
      <geometry>
        <mesh filename="package://centauro/centauro_urdf/meshes/simplified/hip-pitch.stl" scale="0.001 0.001 0.001"/>
      </geometry>
    </visual>
    <collision>
      <origin rpy="0.0 0.0 0.0" xyz="0.0 0.0 0.0"/>
      <geometry>
        <mesh filename="package://centauro/centauro_urdf/meshes/convex_hull/hip-pitch.stl" scale="0.001 0.001 0.001"/>
      </geometry>
    </collision>
  </link>
  <link name="knee_4">
    <inertial>
      <origin xyz="0.10881667 0.0001089081 -0.022638996"/>
      <mass value="1.9356754"/>
      <!-- org: 3.5, foot un modeled-->
      <inertia ixx="0.0030534242" ixy="-4.22079e-05" ixz="0.0013679297" iyy="0.019603321" iyz="6.9941e-06" izz="0.019849817"/>
      <!--  <inertia ixx="0.01" ixy="0.01" ixz="0.01" iyy="0.01" iyz="0.01" izz="0.01"/>  -->
    </inertial>
    <visual>
      <origin rpy="0.0 0.0 0.0" xyz="0.0 0.0 0.0"/>
      <geometry>
        <mesh filename="package://centauro/centauro_urdf/meshes/simplified/knee.stl" scale="0.001 0.001 0.001"/>
      </geometry>
      <material name="dark_grey"/>
    </visual>
    <collision>
      <origin rpy="0.0 0.0 0.0" xyz="0.0 0.0 0.0"/>
      <geometry>
        <mesh filename="package://centauro/centauro_urdf/meshes/convex_hull/knee.stl" scale="0.001 0.001 0.001"/>
      </geometry>
    </collision>
  </link>
  <link name="ankle1_4">
    <inertial>
      <origin xyz="0.032137318 9.73572e-05 -0.0044222206"/>
      <mass value="1.2380744"/>
      <!-- org: 3.5, foot un modeled-->
      <inertia ixx="0.0015610452" ixy="3.30597e-05" ixz="-0.0001314174" iyy="0.0037423211" iyz="-2.12589e-05" izz="0.0038312442"/>
      <!--  <inertia ixx="0.01" ixy="0.01" ixz="0.01" iyy="0.01" iyz="0.01" izz="0.01"/>  -->
    </inertial>
    <visual>
      <origin rpy="0.0 0.0 0.0" xyz="0.0 0.0 0.0"/>
      <geometry>
        <mesh filename="package://centauro/centauro_urdf/meshes/simplified/ankle-pitch.stl" scale="0.001 0.001 0.001"/>
      </geometry>
    </visual>
    <collision>
      <origin rpy="0.0 0.0 0.0" xyz="0.0 0.0 0.0"/>
      <geometry>
        <mesh filename="package://centauro/centauro_urdf/meshes/convex_hull/ankle-pitch.stl" scale="0.001 0.001 0.001"/>
      </geometry>
    </collision>
  </link>
  <link name="ankle2_4">
    <inertial>
      <origin xyz="0.0004435803 0.0004389911 0.19392092"/>
      <mass value="1.1565926"/>
      <!-- org: 3.5, foot un modeled-->
      <inertia ixx="0.0049019475" ixy="4.3032e-06" ixz="3.46491e-05" iyy="0.0038724162" iyz="1.7099e-05" izz="0.0021783198"/>
    </inertial>
    <visual>
      <origin rpy="0.0 0.0 0.0" xyz="0.0 0.0 0.0"/>
      <geometry>
        <mesh filename="package://centauro/centauro_urdf/meshes/simplified/ankle-yaw.stl" scale="0.001 0.001 0.001"/>
      </geometry>
      <material name="dark_grey"/>
    </visual>
    <collision>
      <origin rpy="0.0 0.0 0.0" xyz="0.0 0.0 0.0"/>
      <geometry>
        <mesh filename="package://centauro/centauro_urdf/meshes/convex_hull/ankle-yaw.stl" scale="0.001 0.001 0.001"/>
      </geometry>
    </collision>
  </link>
  <link name="wheel_4">
    <inertial>
      <origin xyz="0.0 0.0 0.0024271906"/>
      <mass value="1.7289003"/>
      <!-- org: 3.5, foot un modeled-->
      <inertia ixx="0.0046864297" ixy="0.0" ixz="0.0" iyy="0.0046713489" iyz="0.0" izz="0.0053126029"/>
    </inertial>
    <visual>
      <origin rpy="0.0 0.0 0.0" xyz="0.0 0.0 0.0"/>
      <geometry>
        <mesh filename="package://centauro/centauro_urdf/meshes/simplified/wheel.stl" scale="0.001 0.001 0.001"/>
      </geometry>
      <material name="black"/>
    </visual>
    <collision>
      <origin rpy="0.0 0.0 0.0" xyz="0.0 0.0 0.0"/>
      <geometry>
        <mesh filename="package://centauro/centauro_urdf/meshes/convex_hull/wheel.stl" scale="0.001 0.001 0.001"/>
      </geometry>
    </collision>
  </link>
  <joint name="hip_yaw_4" type="revolute">
    <parent link="pelvis"/>
    <child link="hip1_4"/>
    <origin rpy="3.14159265359 0.0 3.64869135224" xyz="-0.25 -0.125 -0.0566"/>
    <axis xyz="0 0 1"/>
    <limit effort="304" lower="-2.0" upper="2.48" velocity="8.8"/>
  </joint>
  <joint name="hip_pitch_4" type="revolute">
    <parent link="hip1_4"/>
    <child link="hip2_4"/>
    <origin rpy="1.57079632679 0.0 0.50709869865" xyz="0.0 0.0 0.059"/>
    <axis xyz="0 0 1"/>
    <limit effort="304" lower="-2.09439510" upper="2.09439510" velocity="8.8"/>
  </joint>
  <joint name="knee_pitch_4" type="revolute">
    <parent link="hip2_4"/>
    <child link="knee_4"/>
    <origin rpy="3.14159265359 0.0 1.57079632679" xyz="0.0 0.3 -0.0036"/>
    <axis xyz="0 0 1"/>
    <limit effort="304" lower="-2.61799388" upper="2.61799388" velocity="8.8"/>
  </joint>
  <joint name="ankle_pitch_4" type="revolute">
    <parent link="knee_4"/>
    <child link="ankle1_4"/>
    <origin rpy="3.14159265359 0.0 0.0" xyz="0.2 0.0 -0.10015"/>
    <axis xyz="0 0 1"/>
    <limit effort="147" lower="-2.61799388" upper="2.61799388" velocity="8.1"/>
  </joint>
  <joint name="ankle_yaw_4" type="revolute">
    <parent link="ankle1_4"/>
    <child link="ankle2_4"/>
    <origin rpy="1.57079632679 0.0 1.57079632679" xyz="0.0 0.0 0.0"/>
    <axis xyz="0 0 1"/>
    <limit effort="35" lower="-2.5" upper="2.5" velocity="20.0"/>
  </joint>
  <joint name="j_wheel_4" type="continuous">
    <parent link="ankle2_4"/>
    <child link="wheel_4"/>
    <origin rpy="1.57079632679 0.0 0.0" xyz="0.0 0.00085 0.235"/>
    <axis xyz="0 0 -1"/>
    <limit effort="35" velocity="20.0" lower="-1000000000000000" upper="1000000000000000"/>
  </joint>
  <transmission name="t_hip_yaw_4">
    <type> transmission_interface/SimpleTransmission</type>
    <joint name="hip_yaw_4">
      <hardwareInterface>EffortJointInterface</hardwareInterface>
    </joint>
    <actuator name="motor_hip_yaw_4">
      <hardwareInterface>EffortJointInterface</hardwareInterface>
      <machanicalReduction>1</machanicalReduction>
    </actuator>
    <robotNamespace>/centauro</robotNamespace>
  </transmission>
  <transmission name="t_hip_pitch_4">
    <type> transmission_interface/SimpleTransmission</type>
    <joint name="hip_pitch_4">
      <hardwareInterface>EffortJointInterface</hardwareInterface>
    </joint>
    <actuator name="motor_hip_pitch_4">
      <hardwareInterface>EffortJointInterface</hardwareInterface>
      <machanicalReduction>1</machanicalReduction>
    </actuator>
    <robotNamespace>/centauro</robotNamespace>
  </transmission>
  <transmission name="t_knee_pitch_4">
    <type> transmission_interface/SimpleTransmission</type>
    <joint name="knee_pitch_4">
      <hardwareInterface>EffortJointInterface</hardwareInterface>
    </joint>
    <actuator name="motor_knee_pitch_4">
      <hardwareInterface>EffortJointInterface</hardwareInterface>
      <machanicalReduction>1</machanicalReduction>
    </actuator>
    <robotNamespace>/centauro</robotNamespace>
  </transmission>
  <transmission name="t_ankle_pitch_4">
    <type> transmission_interface/SimpleTransmission</type>
    <joint name="ankle_pitch_4">
      <hardwareInterface>EffortJointInterface</hardwareInterface>
    </joint>
    <actuator name="motor_ankle_pitch_4">
      <hardwareInterface>EffortJointInterface</hardwareInterface>
      <machanicalReduction>1</machanicalReduction>
    </actuator>
    <robotNamespace>/centauro</robotNamespace>
  </transmission>
  <transmission name="t_ankle_yaw_4">
    <type> transmission_interface/SimpleTransmission</type>
    <joint name="ankle_yaw_4">
      <hardwareInterface>EffortJointInterface</hardwareInterface>
    </joint>
    <actuator name="motor_ankle_yaw_4">
      <hardwareInterface>EffortJointInterface</hardwareInterface>
      <machanicalReduction>1</machanicalReduction>
    </actuator>
    <robotNamespace>/centauro</robotNamespace>
  </transmission>
  <transmission name="t_j_wheel_4">
    <type> transmission_interface/SimpleTransmission</type>
    <joint name="j_wheel_4">
      <hardwareInterface>EffortJointInterface</hardwareInterface>
    </joint>
    <actuator name="motor_j_wheel_4">
      <hardwareInterface>EffortJointInterface</hardwareInterface>
      <machanicalReduction>1</machanicalReduction>
    </actuator>
    <robotNamespace>/centauro</robotNamespace>
  </transmission>
  <!-- /actuators -->
  <!-- /legs -->
</robot>
