<?xml version='1.0' encoding='utf-8'?>
<robot name="talos">
  <link name="torso_2_link">
    <inertial>
      <mass value="16.97403" />
      <inertia ixx="0.44372633826" ixy="0.00069132133" ixz="-0.01218206353" iyy="0.2998576068" iyz="-0.00019623338" izz="0.32201554742" />
      <origin rpy="0 0 0" xyz="-0.0463563 -0.00099023 0.1452805" />
    </inertial>
    <visual>
      <origin rpy="0 0 0" xyz="0 0 0" />
      <geometry>
        <mesh filename="package://talos_description/meshes/torso/torso_2.STL" scale="1 1 1" />
      </geometry>
      <material name="LightGrey" />
    </visual>
    <collision>
      <origin rpy="0 0 0" xyz="0 0 0" />
      <geometry>
        <mesh filename="package://talos_description/meshes/torso/torso_2_collision.STL" scale="1 1 1" />
      </geometry>
    </collision>
  </link>
  <link name="torso_1_link">
    <inertial>
      <mass value="2.294658" />
      <inertia ixx="0.00638508087" ixy="-7.107e-08" ixz="-3.065592e-05" iyy="0.00410256102" iyz="-1.46946e-06" izz="0.00622968815" />
      <origin rpy="0 0 0" xyz="0.00078223 3.528e-05 -0.01782457" />
    </inertial>
    <visual>
      <origin rpy="0 0 0" xyz="0 0 0" />
      <geometry>
        <mesh filename="package://talos_description/meshes/torso/torso_1.STL" scale="1 1 1" />
      </geometry>
      <material name="LightGrey" />
    </visual>
    <collision>
      <origin rpy="0 0 0" xyz="0 0 0" />
      <geometry>
        <mesh filename="package://talos_description/meshes/torso/torso_1.STL" scale="1 1 1" />
      </geometry>
    </collision>
  </link>
  <joint name="torso_1_joint" type="revolute">
    <parent link="base_link" />
    <child link="torso_1_link" />
    <origin rpy="0.0 0.0 0.0" xyz="0.0 0.0 0.0722" />
    <axis xyz="0 0 1" />
    <limit effort="200.0" lower="-1.25663706144" upper="1.25663706144" velocity="5.4" />
    <dynamics damping="1.0" friction="1.0" />
  </joint>
  <link name="base_link">
    <inertial>
      <mass value="15.36284" />
      <inertia ixx="0.20105075811" ixy="0.00023244734" ixz="0.0040167728" iyy="0.08411496729" iyz="-0.00087206649" izz="0.2318908414" />
      <origin rpy="0 0 0" xyz="-0.05709419 0.00153054 -0.0762521" />
    </inertial>
    <visual>
      <origin rpy="0 0 0" xyz="0 0 0" />
      <geometry>
        <mesh filename="package://talos_description/meshes/torso/base_link.STL" scale="1 1 1" />
      </geometry>
      <material name="LightGrey" />
    </visual>
    <collision>
      <origin rpy="0 0 0" xyz="0 0 0" />
      <geometry>
        <mesh filename="package://talos_description/meshes/torso/base_link_collision.STL" scale="1 1 1" />
      </geometry>
    </collision>
  </link>
  <joint name="torso_2_joint" type="revolute">
    <parent link="torso_1_link" />
    <child link="torso_2_link" />
    <origin rpy="0.0 0.0 0.0" xyz="0.0 0.0 0.0" />
    <axis xyz="0 1 0" />
    <limit effort="200.0" lower="-0.226892802759" upper="0.733038285838" velocity="5.4" />
    <dynamics damping="1.0" friction="1.0" />
  </joint>
  <link name="imu_link">
    <inertial>
      <mass value="0.01" />
      <inertia ixx="1e-06" ixy="0" ixz="0" iyy="1e-06" iyz="0" izz="1e-06" />
      <origin rpy="0 0 0" xyz="0 0 0" />
    </inertial>
    <visual>
      <origin rpy="0 0 0" xyz="0 0 0" />
      <geometry>
        <box size="0.01 0.01 0.01" />
      </geometry>
    </visual>
  </link>
  <joint name="imu_joint" type="fixed">
    <origin rpy="3.14159265359 0 1.57079632679" xyz="0.04925 0 0.078" />
    <parent link="torso_2_link" />
    <child link="imu_link" />
  </joint>
  <link name="head_1_link">
    <inertial>
      <mass value="0.73746" />
      <inertia ixx="0.00224878584" ixy="4.69375e-06" ixz="8.55557e-05" iyy="0.00111158492" iyz="-4.132536e-05" izz="0.00205225921" />
      <origin rpy="0 0 0" xyz="-0.00157211 -0.00157919 0.02175767" />
    </inertial>
    <visual>
      <origin rpy="0 0 0" xyz="0 0 0" />
      <geometry>
        <mesh filename="package://talos_description/meshes/head/head_1.stl" scale="1 1 1" />
      </geometry>
      <material name="DarkGrey" />
    </visual>
    <collision>
      <origin rpy="0 0 0" xyz="0 0 0" />
      <geometry>
        <mesh filename="package://talos_description/meshes/head/head_1_collision.stl" scale="1 1 1" />
      </geometry>
    </collision>
  </link>
  <joint name="head_1_joint" type="revolute">
    <parent link="torso_2_link" />
    <child link="head_1_link" />
    <origin rpy="0.0 0.0 0.0" xyz="0.02000 0.00000 0.32100" />
    <axis xyz="0 1 0" />
    <limit effort="8.0" lower="-0.209439510239" upper="0.785398163397" velocity="3.0" />
    <dynamics damping="0.5" friction="1.0" />
  </joint>
  <link name="head_2_link">
    <inertial>
      <mass value="1.443954" />
      <inertia ixx="0.01084624339" ixy="1.050889e-05" ixz="0.00041594252" iyy="0.0109569176" iyz="2.367831e-05" izz="0.00571698895" />
      <origin rpy="0 0 0" xyz="0.01002657 5.218e-05 0.14136068" />
    </inertial>
    <visual>
      <origin rpy="0 0 0" xyz="0 0 0" />
      <geometry>
        <mesh filename="package://talos_description/meshes/head/head_2.stl" scale="1 1 1" />
      </geometry>
      <material name="LightGrey" />
    </visual>
    <collision>
      <origin rpy="0 0 0" xyz="0 0 0" />
      <geometry>
        <mesh filename="package://talos_description/meshes/head/head_2_collision.stl" scale="1 1 1" />
      </geometry>
    </collision>
  </link>
  <joint name="head_2_joint" type="revolute">
    <parent link="head_1_link" />
    <child link="head_2_link" />
    <origin rpy="0.0 0.0 0.0" xyz="0.00000 0.00000 0.00000" />
    <axis xyz="0 0 1" />
    <limit effort="4.0" lower="-1.308996939" upper="1.308996939" velocity="3.0" />
    <dynamics damping="0.5" friction="1.0" />
  </joint>
  <joint name="rgbd_joint" type="fixed">
    <origin rpy="0.0 0.0 0.0" xyz="0.066 0.0 0.1982" />
    <axis xyz="0 0 1" />
    <parent link="head_2_link" />
    <child link="rgbd_link" />
  </joint>
  <link name="rgbd_link">
    <inertial>
      <mass value="0.01" />
      <inertia ixx="3e-05" ixy="0" ixz="0" iyy="2e-06" iyz="0" izz="3e-05" />
      <origin rpy="0 0 0" xyz="-0.01 0.0025 0" />
    </inertial>
    <visual>
      <origin rpy="0 0 0" xyz="0 0 0" />
      <geometry>
        <mesh filename="package://talos_description/meshes/sensors/orbbec/orbbec.STL" />
      </geometry>
      <material name="DarkGrey">
        <color rgba="0.5 0.5 0.5 1" />
      </material>
    </visual>
    <collision>
      <origin rpy="0 0 0" xyz="-0.01 0.0025 0" />
      <geometry>
        <box size="0.04 0.185 0.03" />
      </geometry>
    </collision>
  </link>
  <joint name="rgbd_optical_joint" type="fixed">
    <origin rpy="-1.57079632679 0 -1.57079632679" xyz="0 0 0" />
    <parent link="rgbd_link" />
    <child link="rgbd_optical_frame" />
  </joint>
  <link name="rgbd_optical_frame">
    <inertial>
      <mass value="0.01" />
      <inertia ixx="0" ixy="0" ixz="0" iyy="0" iyz="0" izz="0" />
      <origin rpy="0 0 0" xyz="0 0 0" />
    </inertial>
  </link>
  <joint name="rgbd_depth_joint" type="fixed">
    <origin rpy="0 0 0" xyz="0.0 0.03751 0.0" />
    <parent link="rgbd_link" />
    <child link="rgbd_depth_frame" />
  </joint>
  <link name="rgbd_depth_frame" />
  <joint name="rgbd_depth_optical_joint" type="fixed">
    <origin rpy="-1.57079632679 0.0 -1.57079632679" xyz="0 0 0" />
    <parent link="rgbd_depth_frame" />
    <child link="rgbd_depth_optical_frame" />
  </joint>
  <link name="rgbd_depth_optical_frame" />
  <joint name="rgbd_rgb_joint" type="fixed">
    <origin rpy="0 0 0" xyz="0.0 0.01251 0.0" />
    <parent link="rgbd_link" />
    <child link="rgbd_rgb_frame" />
  </joint>
  <link name="rgbd_rgb_frame" />
  <joint name="rgbd_rgb_optical_joint" type="fixed">
    <origin rpy="-1.57079632679 0.0 -1.57079632679" xyz="0 0 0" />
    <parent link="rgbd_rgb_frame" />
    <child link="rgbd_rgb_optical_frame" />
  </joint>
  <link name="rgbd_rgb_optical_frame" />
  <link name="arm_left_1_link">
    <inertial>
      <mass value="2.714567" />
      <inertia ixx="0.01237818683" ixy="-3.625571e-05" ixz="7.14472e-05" iyy="0.004191372" iyz="-0.00023639064" izz="0.01358161109" />
      <origin rpy="0 0 0" xyz="-0.0002762 0.10060223 0.04437419" />
    </inertial>
    <visual>
      <origin rpy="0 0 0" xyz="0 0 0" />
      <geometry>
        <mesh filename="package://talos_description/meshes/arm/arm_1.STL" scale="1 1 1" />
      </geometry>
      <material name="DarkGrey" />
    </visual>
    <collision>
      <origin rpy="0 0 0" xyz="0 0 0" />
      <geometry>
        <mesh filename="package://talos_description/meshes/arm/arm_1_collision.STL" scale="1 1 1" />
      </geometry>
    </collision>
  </link>
  <joint name="arm_left_1_joint" type="revolute">
    <parent link="torso_2_link" />
    <child link="arm_left_1_link" />
    <origin rpy="0.0 0.0 0.0" xyz="0.00000 0.1575 0.23200" />
    <axis xyz="0 0 1" />
    <limit effort="100.0" lower="-1.57079632679" upper="0.785398163397" velocity="2.7" />
    <dynamics damping="1.0" friction="1.0" />
  </joint>
  <link name="arm_left_2_link">
    <inertial>
      <mass value="2.425086" />
      <inertia ixx="0.01297822101" ixy="1.208791e-05" ixz="-0.00320370433" iyy="0.01380870278" iyz="-0.00012770059" izz="0.00478856621" />
      <origin rpy="0 0 0" xyz="0.01438831 0.00092938 -0.08684268" />
    </inertial>
    <visual>
      <origin rpy="0 0 0" xyz="0 0 0" />
      <geometry>
        <mesh filename="package://talos_description/meshes/arm/arm_2.STL" scale="1 1 1" />
      </geometry>
      <material name="DarkGrey" />
    </visual>
    <collision>
      <origin rpy="0 0 0" xyz="0 0 0" />
      <geometry>
        <mesh filename="package://talos_description/meshes/arm/arm_2_collision.STL" scale="1 1 1" />
      </geometry>
    </collision>
  </link>
  <joint name="arm_left_2_joint" type="revolute">
    <parent link="arm_left_1_link" />
    <child link="arm_left_2_link" />
    <origin rpy="0.0 0.0 0.0" xyz="0.00493 0.1365 0.04673" />
    <axis xyz="1 0 0" />
    <limit effort="100.0" lower="0.00872664625997" upper="2.87106661953" velocity="3.66" />
    <dynamics damping="1.0" friction="1.0" />
  </joint>
  <link name="arm_left_3_link">
    <inertial>
      <mass value="2.208741" />
      <inertia ixx="0.00718831493" ixy="-0.00011563551" ixz="0.00075969733" iyy="0.00693528503" iyz="0.00042134743" izz="0.00388359007" />
      <origin rpy="0 0 0" xyz="0.0136084 0.01241619 -0.2499004" />
    </inertial>
    <visual>
      <origin rpy="0 0 0" xyz="0 0 0" />
      <geometry>
        <mesh filename="package://talos_description/meshes/arm/arm_3.STL" scale="1 1 1" />
      </geometry>
      <material name="DarkGrey" />
    </visual>
    <collision>
      <origin rpy="0 0 0" xyz="0 0 0" />
      <geometry>
        <mesh filename="package://talos_description/meshes/arm/arm_3_collision.STL" scale="1 1 1" />
      </geometry>
    </collision>
  </link>
  <joint name="arm_left_3_joint" type="revolute">
    <parent link="arm_left_2_link" />
    <child link="arm_left_3_link" />
    <origin rpy="0.0 0.0 0.0" xyz="0.00000 0.00000 0.00000" />
    <axis xyz="0 0 1" />
    <limit effort="70.0" lower="-2.42600766027" upper="2.42600766027" velocity="4.58" />
    <dynamics damping="1.0" friction="1.0" />
  </joint>
  <link name="arm_left_4_link">
    <inertial>
      <mass value="0.877346" />
      <inertia ixx="0.00251207716" ixy="0.00010070062" ixz="-0.00032788214" iyy="0.00275869324" iyz="0.00040022227" izz="0.00120735959" />
      <origin rpy="0 0 0" xyz="-0.00742138 -0.0213895 -0.03312656" />
    </inertial>
    <visual>
      <origin rpy="0 0 0" xyz="0 0 0" />
      <geometry>
        <mesh filename="package://talos_description/meshes/arm/arm_4.STL" scale="1 1 1" />
      </geometry>
      <material name="DarkGrey" />
    </visual>
    <collision>
      <origin rpy="0 0 0" xyz="0 0 0" />
      <geometry>
        <mesh filename="package://talos_description/meshes/arm/arm_4_collision.STL" scale="1 1 1" />
      </geometry>
    </collision>
  </link>
  <joint name="arm_left_4_joint" type="revolute">
    <parent link="arm_left_3_link" />
    <child link="arm_left_4_link" />
    <origin rpy="0.0 0.0 0.0" xyz="0.02000 0.00000 -0.27300" />
    <axis xyz="0 1 0" />
    <limit effort="70.0" lower="-2.23402144255" upper="-0.00349065850399" velocity="4.58" />
    <dynamics damping="1.0" friction="1.0" />
  </joint>
  <link name="arm_left_5_link">
    <inertial>
      <mass value="1.877923" />
      <inertia ixx="0.00349507283" ixy="1.265489e-05" ixz="1.038286e-05" iyy="0.00436830072" iyz="-9.736042e-05" izz="0.0022826337" />
      <origin rpy="0 0 0" xyz="-6e-05 0.003262 0.079625" />
    </inertial>
    <visual>
      <origin rpy="0 0 0" xyz="0 0 0" />
      <geometry>
        <mesh filename="package://talos_description/meshes/arm/arm_5.STL" scale="1 1 1" />
      </geometry>
      <material name="LightGrey" />
    </visual>
    <collision>
      <origin rpy="0 0 0" xyz="0 0 0" />
      <geometry>
        <mesh filename="package://talos_description/meshes/arm/arm_5_collision.STL" scale="1 1 1" />
      </geometry>
    </collision>
  </link>
  <joint name="arm_left_5_joint" type="revolute">
    <parent link="arm_left_4_link" />
    <child link="arm_left_5_link" />
    <origin rpy="0.0 0.0 0.0" xyz="-0.02000 0.00000 -0.26430" />
    <axis xyz="0 0 1" />
    <limit effort="20.0" lower="-2.51327412287" upper="2.51327412287" velocity="1.95" />
    <dynamics damping="1.0" friction="1.0" />
  </joint>
  <link name="arm_left_6_link">
    <inertial>
      <mass value="0.40931" />
      <inertia ixx="0.00010700023" ixy="-8.899e-08" ixz="-4.392e-08" iyy="0.00014101316" iyz="4.1702e-07" izz="0.00015398658" />
      <origin rpy="0 0 0" xyz="2.1e-05 -0.001965 -0.000591" />
    </inertial>
    <visual>
      <origin rpy="0 0 0" xyz="0 0 0" />
      <geometry>
        <mesh filename="package://talos_description/meshes/arm/arm_6.STL" scale="1 1 1" />
      </geometry>
      <material name="LightGrey" />
    </visual>
    <collision>
      <origin rpy="0 0 0" xyz="0 0 0" />
      <geometry>
        <mesh filename="package://talos_description/meshes/arm/arm_6_collision.STL" scale="1 1 1" />
      </geometry>
    </collision>
  </link>
  <joint name="arm_left_6_joint" type="revolute">
    <parent link="arm_left_5_link" />
    <child link="arm_left_6_link" />
    <origin rpy="0.0 0.0 0.0" xyz="0.00000 0.00000 0.00000" />
    <axis xyz="1 0 0" />
    <limit effort="8.0" lower="-1.37008346282" upper="1.37008346282" velocity="1.76" />
    <dynamics damping="1.0" friction="1.0" />
  </joint>
  <link name="arm_left_7_link">
    <inertial>
      <mass value="0.308441" />
      <inertia ixx="0.00030894317" ixy="-1.58687e-06" ixz="1.73418e-06" iyy="0.00021886181" iyz="-1.221167e-05" izz="0.00017519492" />
      <origin rpy="0 0 0" xyz="0.007525 0.001378 -0.02463" />
    </inertial>
    <visual>
      <origin rpy="0 0 0" xyz="0 0 0" />
      <geometry>
        <mesh filename="package://talos_description/meshes/arm/arm_7.STL" scale="1 1 1" />
      </geometry>
      <material name="DarkGrey" />
    </visual>
    <collision>
      <origin rpy="0 0 0" xyz="0 0 0" />
      <geometry>
        <mesh filename="package://talos_description/meshes/arm/arm_7_collision.STL" scale="1 1 1" />
      </geometry>
    </collision>
  </link>
  <joint name="arm_left_7_joint" type="revolute">
    <parent link="arm_left_6_link" />
    <child link="arm_left_7_link" />
    <origin rpy="0.0 0.0 0.0" xyz="0.0 0.0 0.0" />
    <axis xyz="0 1 0" />
    <limit effort="8.0" lower="-0.680678408278" upper="0.680678408278" velocity="1.76" />
    <dynamics damping="1.0" friction="1.0" />
  </joint>
  <link name="arm_right_1_link">
    <inertial>
      <mass value="2.714567" />
      <inertia ixx="0.01237818683" ixy="3.625571e-05" ixz="7.14472e-05" iyy="0.004191372" iyz="0.00023639064" izz="0.01358161109" />
      <origin rpy="0 0 0" xyz="-0.0002762 -0.10060223 0.04437419" />
    </inertial>
    <visual>
      <origin rpy="0 0 0" xyz="0 0 0" />
      <geometry>
        <mesh filename="package://talos_description/meshes/arm/arm_1.STL" scale="1 -1 1" />
      </geometry>
      <material name="DarkGrey" />
    </visual>
    <collision>
      <origin rpy="0 0 0" xyz="0 0 0" />
      <geometry>
        <mesh filename="package://talos_description/meshes/arm/arm_1_collision.STL" scale="1 -1 1" />
      </geometry>
    </collision>
  </link>
  <joint name="arm_right_1_joint" type="revolute">
    <parent link="torso_2_link" />
    <child link="arm_right_1_link" />
    <origin rpy="0.0 0.0 0.0" xyz="0.00000 -0.1575 0.23200" />
    <axis xyz="0 0 1" />
    <limit effort="100.0" lower="-0.785398163397" upper="1.57079632679" velocity="2.7" />
    <dynamics damping="1.0" friction="1.0" />
  </joint>
  <link name="arm_right_2_link">
    <inertial>
      <mass value="2.425086" />
      <inertia ixx="0.01297822101" ixy="-1.208791e-05" ixz="-0.00320370433" iyy="0.01380870278" iyz="0.00012770059" izz="0.00478856621" />
      <origin rpy="0 0 0" xyz="0.01438831 -0.00092938 -0.08684268" />
    </inertial>
    <visual>
      <origin rpy="0 0 0" xyz="0 0 0" />
      <geometry>
        <mesh filename="package://talos_description/meshes/arm/arm_2.STL" scale="1 -1 1" />
      </geometry>
      <material name="DarkGrey" />
    </visual>
    <collision>
      <origin rpy="0 0 0" xyz="0 0 0" />
      <geometry>
        <mesh filename="package://talos_description/meshes/arm/arm_2_collision.STL" scale="1 -1 1" />
      </geometry>
    </collision>
  </link>
  <joint name="arm_right_2_joint" type="revolute">
    <parent link="arm_right_1_link" />
    <child link="arm_right_2_link" />
    <origin rpy="0.0 0.0 0.0" xyz="0.00493 -0.1365 0.04673" />
    <axis xyz="1 0 0" />
    <limit effort="100.0" lower="-2.87106661953" upper="-0.00872664625997" velocity="3.66" />
    <dynamics damping="1.0" friction="1.0" />
  </joint>
  <link name="arm_right_3_link">
    <inertial>
      <mass value="2.208741" />
      <inertia ixx="0.00718831493" ixy="0.00011563551" ixz="0.00075969733" iyy="0.00693528503" iyz="-0.00042134743" izz="0.00388359007" />
      <origin rpy="0 0 0" xyz="0.0136084 -0.01241619 -0.2499004" />
    </inertial>
    <visual>
      <origin rpy="0 0 0" xyz="0 0 0" />
      <geometry>
        <mesh filename="package://talos_description/meshes/arm/arm_3.STL" scale="1 -1 1" />
      </geometry>
      <material name="DarkGrey" />
    </visual>
    <collision>
      <origin rpy="0 0 0" xyz="0 0 0" />
      <geometry>
        <mesh filename="package://talos_description/meshes/arm/arm_3_collision.STL" scale="1 -1 1" />
      </geometry>
    </collision>
  </link>
  <joint name="arm_right_3_joint" type="revolute">
    <parent link="arm_right_2_link" />
    <child link="arm_right_3_link" />
    <origin rpy="0.0 0.0 0.0" xyz="0.00000 0.00000 0.00000" />
    <axis xyz="0 0 1" />
    <limit effort="70.0" lower="-2.42600766027" upper="2.42600766027" velocity="4.58" />
    <dynamics damping="1.0" friction="1.0" />
  </joint>
  <link name="arm_right_4_link">
    <inertial>
      <mass value="0.877346" />
      <inertia ixx="0.00251207716" ixy="-0.00010070062" ixz="-0.00032788214" iyy="0.00275869324" iyz="-0.00040022227" izz="0.00120735959" />
      <origin rpy="0 0 0" xyz="-0.00742138 0.0213895 -0.03312656" />
    </inertial>
    <visual>
      <origin rpy="0 0 0" xyz="0 0 0" />
      <geometry>
        <mesh filename="package://talos_description/meshes/arm/arm_4.STL" scale="1 -1 1" />
      </geometry>
      <material name="DarkGrey" />
    </visual>
    <collision>
      <origin rpy="0 0 0" xyz="0 0 0" />
      <geometry>
        <mesh filename="package://talos_description/meshes/arm/arm_4_collision.STL" scale="1 -1 1" />
      </geometry>
    </collision>
  </link>
  <joint name="arm_right_4_joint" type="revolute">
    <parent link="arm_right_3_link" />
    <child link="arm_right_4_link" />
    <origin rpy="0.0 0.0 0.0" xyz="0.02000 0.00000 -0.27300" />
    <axis xyz="0 1 0" />
    <limit effort="70.0" lower="-2.23402144255" upper="-0.00349065850399" velocity="4.58" />
    <dynamics damping="1.0" friction="1.0" />
  </joint>
  <link name="arm_right_5_link">
    <inertial>
      <mass value="1.877923" />
      <inertia ixx="0.00349507283" ixy="-1.265489e-05" ixz="1.038286e-05" iyy="0.00436830072" iyz="9.736042e-05" izz="0.0022826337" />
      <origin rpy="0 0 0" xyz="-6e-05 -0.003262 0.079625" />
    </inertial>
    <visual>
      <origin rpy="0 0 0" xyz="0 0 0" />
      <geometry>
        <mesh filename="package://talos_description/meshes/arm/arm_5.STL" scale="1 -1 1" />
      </geometry>
      <material name="LightGrey" />
    </visual>
    <collision>
      <origin rpy="0 0 0" xyz="0 0 0" />
      <geometry>
        <mesh filename="package://talos_description/meshes/arm/arm_5_collision.STL" scale="1 -1 1" />
      </geometry>
    </collision>
  </link>
  <joint name="arm_right_5_joint" type="revolute">
    <parent link="arm_right_4_link" />
    <child link="arm_right_5_link" />
    <origin rpy="0.0 0.0 0.0" xyz="-0.02000 0.00000 -0.26430" />
    <axis xyz="0 0 1" />
    <limit effort="20.0" lower="-2.51327412287" upper="2.51327412287" velocity="1.95" />
    <dynamics damping="1.0" friction="1.0" />
  </joint>
  <link name="arm_right_6_link">
    <inertial>
      <mass value="0.40931" />
      <inertia ixx="0.00010700023" ixy="8.899e-08" ixz="-4.392e-08" iyy="0.00014101316" iyz="-4.1702e-07" izz="0.00015398658" />
      <origin rpy="0 0 0" xyz="2.1e-05 0.001965 -0.000591" />
    </inertial>
    <visual>
      <origin rpy="0 0 0" xyz="0 0 0" />
      <geometry>
        <mesh filename="package://talos_description/meshes/arm/arm_6.STL" scale="1 -1 1" />
      </geometry>
      <material name="LightGrey" />
    </visual>
    <collision>
      <origin rpy="0 0 0" xyz="0 0 0" />
      <geometry>
        <mesh filename="package://talos_description/meshes/arm/arm_6_collision.STL" scale="1 -1 1" />
      </geometry>
    </collision>
  </link>
  <joint name="arm_right_6_joint" type="revolute">
    <parent link="arm_right_5_link" />
    <child link="arm_right_6_link" />
    <origin rpy="0.0 0.0 0.0" xyz="0.00000 0.00000 0.00000" />
    <axis xyz="1 0 0" />
    <limit effort="8.0" lower="-1.37008346282" upper="1.37008346282" velocity="1.76" />
    <dynamics damping="1.0" friction="1.0" />
  </joint>
  <link name="arm_right_7_link">
    <inertial>
      <mass value="0.308441" />
      <inertia ixx="0.00030894317" ixy="1.58687e-06" ixz="1.73418e-06" iyy="0.00021886181" iyz="1.221167e-05" izz="0.00017519492" />
      <origin rpy="0 0 0" xyz="0.007525 -0.001378 -0.02463" />
    </inertial>
    <visual>
      <origin rpy="0 0 0" xyz="0 0 0" />
      <geometry>
        <mesh filename="package://talos_description/meshes/arm/arm_7.STL" scale="1 -1 1" />
      </geometry>
      <material name="DarkGrey" />
    </visual>
    <collision>
      <origin rpy="0 0 0" xyz="0 0 0" />
      <geometry>
        <mesh filename="package://talos_description/meshes/arm/arm_7_collision.STL" scale="1 -1 1" />
      </geometry>
    </collision>
  </link>
  <joint name="arm_right_7_joint" type="revolute">
    <parent link="arm_right_6_link" />
    <child link="arm_right_7_link" />
    <origin rpy="0.0 0.0 0.0" xyz="0.0 0.0 0.0" />
    <axis xyz="0 1 0" />
    <limit effort="8.0" lower="-0.680678408278" upper="0.680678408278" velocity="1.76" />
    <dynamics damping="1.0" friction="1.0" />
  </joint>
  <link name="wrist_right_ft_link">
    <inertial>
      <mass value="0.095" />
      <inertia ixx="1.108502e-05" ixy="9.9077e-07" ixz="-2.3811e-07" iyy="1.092725e-05" iyz="2.3137e-07" izz="1.898772e-05" />
      <origin rpy="0 0 0" xyz="-0.001001 0.000995 -0.008108" />
    </inertial>
    <visual>
      <origin rpy="0 0 0" xyz="0 0 0" />
      <geometry>
        <cylinder length="0.0157" radius="0.0225" />
      </geometry>
      <material name="LightGrey" />
    </visual>
    <collision>
      <origin rpy="0 0 0" xyz="0 0 0" />
      <geometry>
        <cylinder length="0.0157" radius="0.0225" />
      </geometry>
    </collision>
  </link>
  <joint name="wrist_right_ft_joint" type="fixed">
    <parent link="arm_right_7_link" />
    <child link="wrist_right_ft_link" />
    <origin rpy="0.0 0 -1.57079632679" xyz="0 0 -0.051" />
  </joint>
  <link name="wrist_right_ft_tool_link">
    <inertial>
      <mass value="0.001" />
      <inertia ixx="0" ixy="0" ixz="0" iyy="0" iyz="0" izz="0" />
      <origin rpy="0 0 0" xyz="0 0 0" />
    </inertial>
    <visual>
      <origin rpy="0 0.0 0" xyz="0.0 0 0" />
      <geometry>
        <cylinder length="0.00975" radius="0.025" />
      </geometry>
      <material name="FlatBlack" />
    </visual>
    <collision>
      <origin rpy="0 0.0 0" xyz="0.0 0 0" />
      <geometry>
        <cylinder length="0.00975" radius="0.025" />
      </geometry>
    </collision>
  </link>
  <joint name="wrist_right_tool_joint" type="fixed">
    <parent link="wrist_right_ft_link" />
    <child link="wrist_right_ft_tool_link" />
    <origin rpy="0 0 -1.57079632679" xyz="0 0 -0.012725" />
  </joint>
  <link name="wrist_left_ft_link">
    <inertial>
      <mass value="0.095" />
      <inertia ixx="1.108502e-05" ixy="9.9077e-07" ixz="-2.3811e-07" iyy="1.092725e-05" iyz="2.3137e-07" izz="1.898772e-05" />
      <origin rpy="0 0 0" xyz="-0.001001 0.000995 -0.008108" />
    </inertial>
    <visual>
      <origin rpy="0 0 0" xyz="0 0 0" />
      <geometry>
        <cylinder length="0.0157" radius="0.0225" />
      </geometry>
      <material name="LightGrey" />
    </visual>
    <collision>
      <origin rpy="0 0 0" xyz="0 0 0" />
      <geometry>
        <cylinder length="0.0157" radius="0.0225" />
      </geometry>
    </collision>
  </link>
  <joint name="wrist_left_ft_joint" type="fixed">
    <parent link="arm_left_7_link" />
    <child link="wrist_left_ft_link" />
    <origin rpy="0.0 0 -4.71238898038" xyz="0 0 -0.051" />
  </joint>
  <link name="wrist_left_ft_tool_link">
    <inertial>
      <mass value="0.001" />
      <inertia ixx="0" ixy="0" ixz="0" iyy="0" iyz="0" izz="0" />
      <origin rpy="0 0 0" xyz="0 0 0" />
    </inertial>
    <visual>
      <origin rpy="0 0.0 0" xyz="0.0 0 0" />
      <geometry>
        <cylinder length="0.00975" radius="0.025" />
      </geometry>
      <material name="FlatBlack" />
    </visual>
    <collision>
      <origin rpy="0 0.0 0" xyz="0.0 0 0" />
      <geometry>
        <cylinder length="0.00975" radius="0.025" />
      </geometry>
    </collision>
  </link>
  <joint name="wrist_left_tool_joint" type="fixed">
    <parent link="wrist_left_ft_link" />
    <child link="wrist_left_ft_tool_link" />
    <origin rpy="0 0 4.71238898038" xyz="0 0 -0.012725" />
  </joint>
  <link name="gripper_left_base_link">
    <inertial>
      <mass value="0.637534" />
      <inertia ixx="0.0005849692" ixy="4.37159e-06" ixz="-1.2589e-05" iyy="0.00067076439" iyz="2.824361e-05" izz="0.00085526645" />
      <origin rpy="0 0 0" xyz="2.8e-05 0.005394 -0.023654" />
    </inertial>
    <visual>
      <origin rpy="0 0 0" xyz="0 0 0" />
      <geometry>
        <mesh filename="package://talos_description/meshes/gripper/base_link.STL" scale="1 1 1" />
      </geometry>
      <material name="DarkGrey" />
    </visual>
    <collision>
      <origin rpy="0 0 0" xyz="0 0 0" />
      <geometry>
        <mesh filename="package://talos_description/meshes/gripper/base_link_collision.STL" scale="1 1 1" />
      </geometry>
    </collision>
  </link>
  <joint name="gripper_left_base_link_joint" type="fixed">
    <parent link="wrist_left_ft_tool_link" />
    <child link="gripper_left_base_link" />
    <origin rpy="0.0 0.0 0.0" xyz="0.00000 0.00000 -0.02875" />
    <axis xyz="0 0 0" />
  </joint>
  <link name="gripper_left_motor_double_link">
    <inertial>
      <mass value="0.134356" />
      <inertia ixx="0.00013479919" ixy="6.184429e-05" ixz="-3.0798e-05" iyy="0.00019602207" iyz="4.707722e-05" izz="0.00024217879" />
      <origin rpy="0 0 0" xyz="0.019654 0.018572 -0.011998" />
    </inertial>
    <visual>
      <origin rpy="0 0 0" xyz="0 0 0" />
      <geometry>
        <mesh filename="package://talos_description/meshes/gripper/gripper_motor_double.STL" scale="1 1 1" />
      </geometry>
      <material name="Orange" />
    </visual>
    <collision>
      <origin rpy="0 0 0" xyz="0 0 0" />
      <geometry>
        <mesh filename="package://talos_description/meshes/gripper/gripper_motor_double_collision.STL" scale="1 1 1" />
      </geometry>
    </collision>
  </link>
  <joint name="gripper_left_joint" type="revolute">
    <parent link="gripper_left_base_link" />
    <child link="gripper_left_motor_double_link" />
    <origin rpy="0.0 0.0 0.0" xyz="0.0 0.02025 -0.03" />
    <axis xyz="1 0 0" />
    <limit effort="1.0" lower="-0.959931088597" upper="0.0" velocity="1.0" />
    <dynamics damping="1.0" friction="1.0" />
  </joint>
  <link name="gripper_right_base_link">
    <inertial>
      <mass value="0.637534" />
      <inertia ixx="0.0005849692" ixy="4.37159e-06" ixz="-1.2589e-05" iyy="0.00067076439" iyz="2.824361e-05" izz="0.00085526645" />
      <origin rpy="0 0 0" xyz="2.8e-05 0.005394 -0.023654" />
    </inertial>
    <visual>
      <origin rpy="0 0 0" xyz="0 0 0" />
      <geometry>
        <mesh filename="package://talos_description/meshes/gripper/base_link.STL" scale="1 1 1" />
      </geometry>
      <material name="DarkGrey" />
    </visual>
    <collision>
      <origin rpy="0 0 0" xyz="0 0 0" />
      <geometry>
        <mesh filename="package://talos_description/meshes/gripper/base_link_collision.STL" scale="1 1 1" />
      </geometry>
    </collision>
  </link>
  <joint name="gripper_right_base_link_joint" type="fixed">
    <parent link="wrist_right_ft_tool_link" />
    <child link="gripper_right_base_link" />
    <origin rpy="0.0 0.0 0.0" xyz="0.00000 0.00000 -0.02875" />
    <axis xyz="0 0 0" />
  </joint>
  <link name="gripper_right_motor_double_link">
    <inertial>
      <mass value="0.134356" />
      <inertia ixx="0.00013479919" ixy="6.184429e-05" ixz="-3.0798e-05" iyy="0.00019602207" iyz="4.707722e-05" izz="0.00024217879" />
      <origin rpy="0 0 0" xyz="0.019654 0.018572 -0.011998" />
    </inertial>
    <visual>
      <origin rpy="0 0 0" xyz="0 0 0" />
      <geometry>
        <mesh filename="package://talos_description/meshes/gripper/gripper_motor_double.STL" scale="1 1 1" />
      </geometry>
      <material name="Orange" />
    </visual>
    <collision>
      <origin rpy="0 0 0" xyz="0 0 0" />
      <geometry>
        <mesh filename="package://talos_description/meshes/gripper/gripper_motor_double_collision.STL" scale="1 1 1" />
      </geometry>
    </collision>
  </link>
  <joint name="gripper_right_joint" type="revolute">
    <parent link="gripper_right_base_link" />
    <child link="gripper_right_motor_double_link" />
    <origin rpy="0.0 0.0 0.0" xyz="0.0 0.02025 -0.03" />
    <axis xyz="1 0 0" />
    <limit effort="1.0" lower="-0.959931088597" upper="0.0" velocity="1.0" />
    <dynamics damping="1.0" friction="1.0" />
  </joint>
  <link name="leg_left_1_link">
    <inertial>
      <mass value="1.845591" />
      <inertia ixx="0.00541533521" ixy="-0.00015428714" ixz="0.00131612622" iyy="0.00848624936" iyz="-1.906103e-05" izz="0.00474512541" />
      <origin rpy="0 0 0" xyz="0.02247868 0.00106736 0.03130665" />
    </inertial>
    <visual>
      <origin rpy="0 0 0" xyz="0 0 0" />
      <geometry>
        <mesh filename="package://talos_description/meshes/v2/hip_z_lo_res.stl" scale="1 1 1" />
      </geometry>
      <material name="DarkGrey" />
    </visual>
    <collision>
      <origin rpy="0 0 0" xyz="0 0 0" />
      <geometry>
        <mesh filename="package://talos_description/meshes/v2/hip_z_collision.stl" scale="1 1 1" />
      </geometry>
    </collision>
  </link>
  <joint name="leg_left_1_joint" type="revolute">
    <parent link="base_link" />
    <child link="leg_left_1_link" />
    <origin rpy="0.0 0.0 0.0" xyz="-0.02 0.085 -0.27105" />
    <axis xyz="0 0 1" />
    <limit effort="100" lower="-0.349065850399" upper="1.57079632679" velocity="3.87" />
    <dynamics damping="0.0" friction="0.0" />
  </joint>
  <link name="leg_left_2_link">
    <inertial>
      <mass value="1.490952" />
      <inertia ixx="0.00497152259" ixy="-0.0001311358" ixz="-4.86648e-06" iyy="0.00190550993" iyz="4.585381e-05" izz="0.00474289754" />
      <origin rpy="0 0 0" xyz="-0.00704703 0.02592659 0.00273385" />
    </inertial>
    <visual>
      <origin rpy="0  0  0" xyz="0 0 0.0" />
      <geometry>
        <mesh filename="package://talos_description/meshes/v2/hip_x_lo_res.stl" scale="1 1 1" />
      </geometry>
      <material name="DarkGrey" />
    </visual>
    <collision>
      <origin rpy="0  0  0" xyz="0 0 0.0" />
      <geometry>
        <mesh filename="package://talos_description/meshes/v2/hip_x_collision.stl" scale="1 1 1" />
      </geometry>
    </collision>
  </link>
  <joint name="leg_left_2_joint" type="revolute">
    <parent link="leg_left_1_link" />
    <child link="leg_left_2_link" />
    <origin rpy="0.0 0.0 0.0" xyz="0.00000 0.00000 0.00000" />
    <axis xyz="1 0 0" />
    <limit effort="160" lower="-0.5236" upper="0.5236" velocity="5.8" />
    <dynamics damping="0.0" friction="0.0" />
  </joint>
  <link name="leg_left_3_link">
    <inertial>
      <mass value="6.239871" />
      <inertia ixx="0.15337403915" ixy="0.00068913396" ixz="0.00168034366" iyy="0.13648139346" iyz="-0.02187635445" izz="0.03001594885" />
      <origin rpy="0 0 0" xyz="0.0058523 0.0636967 -0.18339564" />
    </inertial>
    <visual>
      <origin rpy="0 0 0" xyz="0 0 0" />
      <geometry>
        <mesh filename="package://talos_description/meshes/v2/hip_y_lo_res.stl" scale="1 1 1" />
      </geometry>
      <material name="DarkGrey" />
    </visual>
    <collision>
      <origin rpy="0 0 0" xyz="0 0 0" />
      <geometry>
        <mesh filename="package://talos_description/meshes/v2/hip_y_collision.stl" scale="1 1 1" />
      </geometry>
    </collision>
  </link>
  <joint name="leg_left_3_joint" type="revolute">
    <parent link="leg_left_2_link" />
    <child link="leg_left_3_link" />
    <origin rpy="0.0 0.0 0.0" xyz="0.00000 0.00000 0.00000" />
    <axis xyz="0 1 0" />
    <limit effort="160" lower="-2.095" upper="0.7" velocity="5.8" />
    <dynamics damping="0.0" friction="0.0" />
  </joint>
  <link name="leg_left_4_link">
    <inertial>
      <mass value="3.759951" />
      <inertia ixx="0.04287677484" ixy="0.00043705397" ixz="0.00078292368" iyy="0.03598906971" iyz="0.00037717694" izz="0.01364791564" />
      <origin rpy="0 0 0" xyz="0.01317717 0.02917508 -0.11594602" />
    </inertial>
    <visual>
      <origin rpy="0 0 0" xyz="0 0 0" />
      <geometry>
        <mesh filename="package://talos_description/meshes/v2/knee_lo_res.stl" scale="1 1 1" />
      </geometry>
      <material name="DarkGrey" />
    </visual>
    <collision>
      <origin rpy="0 0 0" xyz="0 0 0" />
      <geometry>
        <mesh filename="package://talos_description/meshes/v2/knee_collision.stl" scale="1 1 1" />
      </geometry>
    </collision>
  </link>
  <joint name="leg_left_4_joint" type="revolute">
    <parent link="leg_left_3_link" />
    <child link="leg_left_4_link" />
    <origin rpy="0.0 0.0 0.0" xyz="0.00000 0.00000 -0.38000" />
    <axis xyz="0 1 0" />
    <limit effort="300" lower="0" upper="2.618" velocity="7" />
    <dynamics damping="0.0" friction="0.0" />
  </joint>
  <link name="leg_left_5_link">
    <inertial>
      <mass value="1.29096" />
      <inertia ixx="0.01143430819" ixy="0.00096978273" ixz="0.00039976581" iyy="0.00888974312" iyz="-0.00277808667" izz="0.00506373875" />
      <origin rpy="0 0 0" xyz="-0.01400838 0.04180064 0.03820186" />
    </inertial>
    <visual>
      <origin rpy="0 0 0" xyz="0 0 0.0" />
      <geometry>
        <mesh filename="package://talos_description/meshes/v2/ankle_Y_lo_res.stl" scale="1 1 1" />
      </geometry>
      <material name="Grey" />
    </visual>
    <collision>
      <origin rpy="0 0 0" xyz="0 0 0.0" />
      <geometry>
        <mesh filename="package://talos_description/meshes/v2/ankle_Y_collision.stl" scale="1 1 1" />
      </geometry>
    </collision>
  </link>
  <joint name="leg_left_5_joint" type="revolute">
    <parent link="leg_left_4_link" />
    <child link="leg_left_5_link" />
    <origin rpy="0.0 0.0 0.0" xyz="0.00000 0.00000 -0.32500" />
    <axis xyz="0 1 0" />
    <limit effort="160" lower="-1.27" upper="0.68" velocity="5.8" />
    <dynamics damping="0.0" friction="0.0" />
  </joint>
  <link name="leg_left_6_link">
    <inertial>
      <mass value="1.597773" />
      <inertia ixx="0.00439027267" ixy="-6.743674e-05" ixz="0.00113816363" iyy="0.00743063029" iyz="3.943143e-05" izz="0.00550906699" />
      <origin rpy="0 0 0" xyz="-0.02034668 -0.00051514 -0.05987428" />
    </inertial>
    <visual>
      <origin rpy="0 0 0" xyz="0 0 0" />
      <geometry>
        <mesh filename="package://talos_description/meshes/v2/ankle_X_lo_res.stl" scale="1 1 1" />
      </geometry>
      <material name="Grey" />
    </visual>
    <collision>
      <origin rpy="0 0 0" xyz="0 0 0" />
      <geometry>
        <mesh filename="package://talos_description/meshes/v2/ankle_X_collision.stl" scale="1 1 1" />
      </geometry>
    </collision>
  </link>
  <joint name="leg_left_6_joint" type="revolute">
    <parent link="leg_left_5_link" />
    <child link="leg_left_6_link" />
    <origin rpy="0.0 0.0 0.0" xyz="0.00000 0.00000 0.00000" />
    <axis xyz="1 0 0" />
    <limit effort="100" lower="-0.5236" upper="0.5236" velocity="4.8" />
    <dynamics damping="0.0" friction="0.0" />
  </joint>
  <link name="imu_link_2">
    <inertial>
      <mass value="0.01" />
      <inertia ixx="1e-06" ixy="0" ixz="0" iyy="1e-06" iyz="0" izz="1e-06" />
      <origin rpy="0 0 0" xyz="0 0 0" />
    </inertial>
    <visual>
      <origin rpy="0 0 0" xyz="0 0 0" />
      <geometry>
        <box size="0.01 0.01 0.01" />
      </geometry>
    </visual>
  </link>
  <joint name="imu_joint_2" type="fixed">
    <origin rpy="3.14159265359 0 1.57079632679" xyz="0.04925 0 0.078" />
    <parent link="leg_left_6_link" />
    <child link="imu_link_2" />
  </joint>
  <link name="left_sole_link">
    <inertial>
      <mass value="0.01" />
      <inertia ixx="0.0001" ixy="0" ixz="0" iyy="0.0001" iyz="0" izz="0.0001" />
      <origin rpy="0 0 0" xyz="0 0 0" />
    </inertial>
  </link>
  <joint name="leg_left_sole_fix_joint" type="fixed">
    <parent link="leg_left_6_link" />
    <child link="left_sole_link" />
    <origin rpy="0 0 0" xyz="0.00 0.00 -0.107" />
    <axis xyz="1 0 0" />
    <dynamics damping="0.0" friction="0.0" />
  </joint>
  <link name="leg_right_1_link">
    <inertial>
      <mass value="1.845591" />
      <inertia ixx="0.00541533521" ixy="0.00015428714" ixz="0.00131612622" iyy="0.00848624936" iyz="1.906103e-05" izz="0.00474512541" />
      <origin rpy="0 0 0" xyz="0.02247868 -0.00106736 0.03130665" />
    </inertial>
    <visual>
      <origin rpy="0 0 0" xyz="0 0 0" />
      <geometry>
        <mesh filename="package://talos_description/meshes/v2/hip_z_lo_res.stl" scale="1 -1 1" />
      </geometry>
      <material name="DarkGrey" />
    </visual>
    <collision>
      <origin rpy="0 0 0" xyz="0 0 0" />
      <geometry>
        <mesh filename="package://talos_description/meshes/v2/hip_z_collision.stl" scale="1 -1 1" />
      </geometry>
    </collision>
  </link>
  <joint name="leg_right_1_joint" type="revolute">
    <parent link="base_link" />
    <child link="leg_right_1_link" />
    <origin rpy="0.0 0.0 0.0" xyz="-0.02 -0.085 -0.27105" />
    <axis xyz="0 0 1" />
    <limit effort="100" lower="-1.57079632679" upper="0.349065850399" velocity="3.87" />
    <dynamics damping="0.0" friction="0.0" />
  </joint>
  <link name="leg_right_2_link">
    <inertial>
      <mass value="1.490952" />
      <inertia ixx="0.00497152259" ixy="0.0001311358" ixz="-4.86648e-06" iyy="0.00190550993" iyz="-4.585381e-05" izz="0.00474289754" />
      <origin rpy="0 0 0" xyz="-0.00704703 -0.02592659 0.00273385" />
    </inertial>
    <visual>
      <origin rpy="0  0  0" xyz="0 0 0.0" />
      <geometry>
        <mesh filename="package://talos_description/meshes/v2/hip_x_lo_res.stl" scale="1 -1 1" />
      </geometry>
      <material name="DarkGrey" />
    </visual>
    <collision>
      <origin rpy="0  0  0" xyz="0 0 0.0" />
      <geometry>
        <mesh filename="package://talos_description/meshes/v2/hip_x_collision.stl" scale="1 -1 1" />
      </geometry>
    </collision>
  </link>
  <joint name="leg_right_2_joint" type="revolute">
    <parent link="leg_right_1_link" />
    <child link="leg_right_2_link" />
    <origin rpy="0.0 0.0 0.0" xyz="0.00000 0.00000 0.00000" />
    <axis xyz="1 0 0" />
    <limit effort="160" lower="-0.5236" upper="0.5236" velocity="5.8" />
    <dynamics damping="0.0" friction="0.0" />
  </joint>
  <link name="leg_right_3_link">
    <inertial>
      <mass value="6.239871" />
      <inertia ixx="0.15337403915" ixy="-0.00068913396" ixz="0.00168034366" iyy="0.13648139346" iyz="0.02187635445" izz="0.03001594885" />
      <origin rpy="0 0 0" xyz="0.0058523 -0.0636967 -0.18339564" />
    </inertial>
    <visual>
      <origin rpy="0 0 0" xyz="0 0 0" />
      <geometry>
        <mesh filename="package://talos_description/meshes/v2/hip_y_lo_res.stl" scale="1 -1 1" />
      </geometry>
      <material name="DarkGrey" />
    </visual>
    <collision>
      <origin rpy="0 0 0" xyz="0 0 0" />
      <geometry>
        <mesh filename="package://talos_description/meshes/v2/hip_y_collision.stl" scale="1 -1 1" />
      </geometry>
    </collision>
  </link>
  <joint name="leg_right_3_joint" type="revolute">
    <parent link="leg_right_2_link" />
    <child link="leg_right_3_link" />
    <origin rpy="0.0 0.0 0.0" xyz="0.00000 0.00000 0.00000" />
    <axis xyz="0 1 0" />
    <limit effort="160" lower="-2.095" upper="0.7" velocity="5.8" />
    <dynamics damping="0.0" friction="0.0" />
  </joint>
  <link name="leg_right_4_link">
    <inertial>
      <mass value="3.759951" />
      <inertia ixx="0.04287677484" ixy="-0.00043705397" ixz="0.00078292368" iyy="0.03598906971" iyz="-0.00037717694" izz="0.01364791564" />
      <origin rpy="0 0 0" xyz="0.01317717 -0.02917508 -0.11594602" />
    </inertial>
    <visual>
      <origin rpy="0 0 0" xyz="0 0 0" />
      <geometry>
        <mesh filename="package://talos_description/meshes/v2/knee_lo_res.stl" scale="1 -1 1" />
      </geometry>
      <material name="DarkGrey" />
    </visual>
    <collision>
      <origin rpy="0 0 0" xyz="0 0 0" />
      <geometry>
        <mesh filename="package://talos_description/meshes/v2/knee_collision.stl" scale="1 -1 1" />
      </geometry>
    </collision>
  </link>
  <joint name="leg_right_4_joint" type="revolute">
    <parent link="leg_right_3_link" />
    <child link="leg_right_4_link" />
    <origin rpy="0.0 0.0 0.0" xyz="0.00000 0.00000 -0.38000" />
    <axis xyz="0 1 0" />
    <limit effort="300" lower="0" upper="2.618" velocity="7" />
    <dynamics damping="0.0" friction="0.0" />
  </joint>
  <link name="leg_right_5_link">
    <inertial>
      <mass value="1.29096" />
      <inertia ixx="0.01143430819" ixy="-0.00096978273" ixz="0.00039976581" iyy="0.00888974312" iyz="0.00277808667" izz="0.00506373875" />
      <origin rpy="0 0 0" xyz="-0.01400838 -0.04180064 0.03820186" />
    </inertial>
    <visual>
      <origin rpy="0 0 0" xyz="0 0 0.0" />
      <geometry>
        <mesh filename="package://talos_description/meshes/v2/ankle_Y_lo_res.stl" scale="1 -1 1" />
      </geometry>
      <material name="Grey" />
    </visual>
    <collision>
      <origin rpy="0 0 0" xyz="0 0 0.0" />
      <geometry>
        <mesh filename="package://talos_description/meshes/v2/ankle_Y_collision.stl" scale="1 -1 1" />
      </geometry>
    </collision>
  </link>
  <joint name="leg_right_5_joint" type="revolute">
    <parent link="leg_right_4_link" />
    <child link="leg_right_5_link" />
    <origin rpy="0.0 0.0 0.0" xyz="0.00000 0.00000 -0.32500" />
    <axis xyz="0 1 0" />
    <limit effort="160" lower="-1.27" upper="0.68" velocity="5.8" />
    <dynamics damping="0.0" friction="0.0" />
  </joint>
  <link name="leg_right_6_link">
    <inertial>
      <mass value="1.597773" />
      <inertia ixx="0.00439027267" ixy="6.743674e-05" ixz="0.00113816363" iyy="0.00743063029" iyz="-3.943143e-05" izz="0.00550906699" />
      <origin rpy="0 0 0" xyz="-0.02034668 0.00051514 -0.05987428" />
    </inertial>
    <visual>
      <origin rpy="0 0 0" xyz="0 0 0" />
      <geometry>
        <mesh filename="package://talos_description/meshes/v2/ankle_X_lo_res.stl" scale="1 -1 1" />
      </geometry>
      <material name="Grey" />
    </visual>
    <collision>
      <origin rpy="0 0 0" xyz="0 0 0" />
      <geometry>
        <mesh filename="package://talos_description/meshes/v2/ankle_X_collision.stl" scale="1 -1 1" />
      </geometry>
    </collision>
  </link>
  <joint name="leg_right_6_joint" type="revolute">
    <parent link="leg_right_5_link" />
    <child link="leg_right_6_link" />
    <origin rpy="0.0 0.0 0.0" xyz="0.00000 0.00000 0.00000" />
    <axis xyz="1 0 0" />
    <limit effort="100" lower="-0.5236" upper="0.5236" velocity="4.8" />
    <dynamics damping="0.0" friction="0.0" />
  </joint>
  <link name="imu_link_3">
    <inertial>
      <mass value="0.01" />
      <inertia ixx="1e-06" ixy="0" ixz="0" iyy="1e-06" iyz="0" izz="1e-06" />
      <origin rpy="0 0 0" xyz="0 0 0" />
    </inertial>
    <visual>
      <origin rpy="0 0 0" xyz="0 0 0" />
      <geometry>
        <box size="0.01 0.01 0.01" />
      </geometry>
    </visual>
  </link>
  <joint name="imu_joint_3" type="fixed">
    <origin rpy="3.14159265359 0 1.57079632679" xyz="0.04925 0 0.078" />
    <parent link="leg_right_6_link" />
    <child link="imu_link_3" />
  </joint>
  <link name="right_sole_link">
    <inertial>
      <mass value="0.01" />
      <inertia ixx="0.0001" ixy="0" ixz="0" iyy="0.0001" iyz="0" izz="0.0001" />
      <origin rpy="0 0 0" xyz="0 0 0" />
    </inertial>
  </link>
  <joint name="leg_right_sole_fix_joint" type="fixed">
    <parent link="leg_right_6_link" />
    <child link="right_sole_link" />
    <origin rpy="0 0 0" xyz="0.00 0.00 -0.107" />
    <axis xyz="1 0 0" />
    <dynamics damping="0.0" friction="0.0" />
  </joint>
  <material name="Blue">
    <color rgba="0.0 0.0 0.8 1.0" />
  </material>
  <material name="Green">
    <color rgba="0.0 0.8 0.0 1.0" />
  </material>
  <material name="Grey">
    <color rgba="0.7 0.7 0.7 1.0" />
  </material>
  <material name="LightGrey">
    <color rgba="0.9 0.9 0.9 1.0" />
  </material>
  <material name="DarkGrey">
    <color rgba="0.2 0.2 0.2 1.0" />
  </material>
  <material name="Red">
    <color rgba="0.8 0.0 0.0 1.0" />
  </material>
  <material name="White">
    <color rgba="1.0 1.0 1.0 1.0" />
  </material>
  <material name="Orange">
    <color rgba="1.0 0.5 0.0 1.0" />
  </material>
</robot>
